Workbook

Sheet Clasificacion
J2: 1 | K2: Academia
J3: 2 | K3: Ean Impacta
J4: 3 | K4: Ean Sostenibilidad
J5: 4 | K5: Biblioteca
J6: 5 | K6: Internacionalización
J7: 6 | K7: Prácticas Profesionales
J8: 7 | K8: Plataformas y soporte
J9: 8 | K9: Registro Académico
J10: 9 | K10: Apoyo y Recursos Financieros
J11: 10 | K11: Canales de comunicación
J12: 11 | K12: Planta física y Servicios logísticos
J13: 12 | K13: Experiencia Estudiantil
... J17: 16 | K17: Comentarios finales

Sheet Siglas
A1: Codigo_Area | B1: Area_PPT_2019 | C1: Codigo_Area | D1: Area_PPT_2020 | G1: Codigo_Area | H1: Area_PPT_2021 | K1: Codigo_Area | L1: Area_PPT_2022
A2: AC1 | B2: Academia | C2: AC1 | D2: Academia | E2: AC1 | G2: D01 | H2: Academia | I2: AC1 | K2: E01 | L2: Academia | M2: AC1
A3: APF1 | B3: Apoyo financiero y tesorería | C3: IES1 | D3: Instituto para el Emprendimiento Sostenible | E3: IES1 | G3: D02 | H3: Planta física y servicios logísticos | I3: PFSL1 | K3: E08 | L3: Mediaciones didácticas | M3: MD1
A4: ASSMC1 | B4: Assessment Center | C4: B1 | D4: Biblioteca | E4: B1 | G4: D03 | H4: Instituto para el Emprendimiento Sostenible | I4: IES1 | K4: E02 | L4: Academia | M4: AC1
A5: B1 | B5: Biblioteca | C5: INT1 | D5: Internacionalización | E5: INT1 | G5: D04 | H5: Biblioteca | I5: B1 | K5: E09 | L5: Assessment Center | M5: ASSMC1
A6: COMENT14 | B6: Comentario abierto | C6: PF1 | D6: Prácticas profesionales | E6: PF1 | G6: D05 | H6: Internacionalización | I6: INT1 | K6: E10 | L6: Academia | M6: AC1
A7: GEE1 | B7: Gerencia de Experiencia Estudiantil | C7: TIC1 | D7: TIC | E7: TIC1 | G7: D06 | H7: Prácticas profesionales | I7: PF1 | K7: E03 | L7: Laboratorios | M7: LAB
A8: IES1 | B8: Instituto para el Emprendimiento Sostenible | C8: MD1 | D8: Mediaciones Didácticas | E8: MD1 | G8: D07 | H8: TIC | I8: TIC1 | K8: E04 | L8: Ean Impacta | M8: EANIMP
A9: INT1 | B9: Internacionalización | C9: RA1 | D9: Registro académico | E9: RA1 | G9: D08 | H9: Mediaciones Didácticas | I9: MD1 | K9: E05 | L9: Biblioteca | M9: B1
A10: MD1 | B10: Mediaciones Didácticas | C10: APF1 | D10: Apoyo financiero y tesorería | E10: APF1 | G10: D09 | H10: Registro académico | I10: RA1 | K10: E06 | L10: Internacionalización | M10: INT1
A11: MC1 | B11: Mercadeo y comunicaciones | C11: MC1 | D11: Mercadeo y comunicaciones | E11: MC1 | G11: D10 | H11: Apoyo financiero y tesorería | I11: APF1 | K11: E07 | L11: Prácticas profesionales | M11: PF1
A12: PFSL1 | B12: Planta física y servicios logísticos | C12: GEE1 | D12: Gerencia de Experiencia Estudiantil | E12: GEE1 | G12: D11 | H12: Centro de contacto y comunicaciones | I12: CC1 | K12: E11 | L12: TIC | M12: TIC1
A13: PF1 | B13: Prácticas profesionales | C13: INST1 | D13: Institucional | E13: INST1 | G13: D11 | H13: Centro de contacto y comunicaciones | I13: CC1 | K13: E12 | L13: Registro académico | M13: RA1
A14: RA1 | B14: Registro académico | D14: Planta física y servicios logísticos | E14: PFSL1 | G14: D12 | H14: Institucional | I14: INST1 | K14: E13 | L14: Apoyo financiero y tesorería | M14: APF1
A15: TIC1 | B15: TIC | G15: D13 | H15: Gerencia de Experiencia Estudiantil | I15: GEE1 | K15: E14 | L15: Mercadeo y comunicaciones | M15: MC1
G16: D14 | H16: Gerencia de Experiencia Estudiantil | I16: GEE1 | K16: E15 | L16: Planta física y servicios logísticos | M16: PFSL1
G17: D15 | H17: Gerencia de Experiencia Estudiantil | I17: GEE1 | K17: E16 | L17: Gerencia de Experiencia Estudiantil | M17: GEE1
G18: D16 | H18: Gerencia de Experiencia Estudiantil | I18: GEE1 | K18: E17 | L18: Gerencia de Experiencia Estudiantil | M18: GEE1
K19: E18 | L19: Gerencia de Experiencia Estudiantil | M19: GEE1
K20: E19 | L20: Gerencia de Experiencia Estudiantil | M20: GEE1
K21: E20 | L21: Gerencia de Experiencia Estudiantil | M21: GEE1
K22: E21 | L22: Horarios de atención | M22: HORA
K23: E22 | L23: Comentario abierto | M23: COMENT14
K24: E12 | L24: Institucional | M24: INST1

Sheet Diccionario preguntas
A1: Área de análisis | B1: Pregunta / Ítem (según presentación 2023)
A2: Academia | B2: Satisfacción con el plan de estudios
A3: Academia | B3: Satisfacción con la pertinencia de los conocimientos adquiridos
A4: Academia | B4: Contribución del programa al proceso formativo
A5: Academia | B5: Cumplimiento de la promesa de valor
A6: Academia | B6: Conocimiento disciplinar del docente
A7: Academia | B7: Competencias docentes
A8: Academia | B8: Cumplimiento del syllabus
A9: Academia | B9: Evaluación y acompañamiento del aprendizaje
A10: Academia | B10: Entrega de calificaciones y retroalimentación
A11: Academia | B11: Calidad humana del docente
A12: Academia | B12: Compromiso docente
... A103: Comentarios finales | B103: Comentarios abiertos generales

Sheet 2019
A1: Codigo pregunta | B1: Pregunta completa | C1: Codigo pregunta | D1: Pregunta abreviada | E1: Largo pregunta abreviada
A2: AC1 | B2: ¿Qué tan satisfecho te encuentras con el programa más reciente que estás cursando en la Universidad Ean? | C2: AC1 | D2: ¿Qué tan satisfecho te encuentras con el programa más reciente que estás cursando en la Universidad Ean? | E2: =LEN(D2) -> 104
A3: AC2 | B3: ¿Qué tan cumplida ha sido la Universidad Ean en relación con el proceso de formación basado en competencias? | C3: AC2 | D3: ¿Qué tan cumplida ha sido la Universidad Ean en relación con el proceso de formación basado en competencias? | E3: =LEN(D3) -> 108
A4: AC3 | B4: En general, ¿Cómo percibes la calidad docente de la Universidad Ean? | C4: AC3 | D4: En general, ¿cómo percibes la calidad docente de la Universidad Ean? | E4: =LEN(D4) -> 68
A5: AC4 | B5: ¿Qué tan fácil han hecho los docentes, el proceso de aprendizaje en el que te encuentras? | C5: AC4 | D5: ¿Qué tan fácil han hecho los docentes el proceso de aprendizaje en el que te encuentras? | E5: =LEN(D5) -> 88
A6: AC5 | B6: ¿Qué tan oportuna es la entrega de evaluaciones por parte de los docentes? | C6: AC5 | D6: ¿Qué tan oportuna es la entrega de evaluaciones por parte de los docentes? | E6: =LEN(D6) -> 74
A7: AC6 | B7: ¿Qué tan competente es el personal de tu facultad? | C7: AC6 | D7: ¿Qué tan competente es el personal de tu facultad? | E7: =LEN(D7) -> 50
A8: AC7 | B8: ¿Qué tan competentes son los responsables de tu programa académico (directores o coordinadores)? | C8: AC7 | D8: ¿Qué tan competentes son los responsables de tu programa académico (directores o coordinadores)? | E8: =LEN(D8) -> 96
A9: AC8 | B9: En general ¿cómo calificas los mecanismos de interacción y comunicación de los colaboradores de tu facultad? | C9: AC8 | D9: En general, ¿cómo calificas los mecanismos de interacción y comunicación de los colaboradores de tu facultad? | E9: =LEN(D9) -> 109
A10: AC9 | B10: ¿Qué tan satisfecho te encuentras con la oferta académica de unidades de estudio? | C10: AC9 | D10: ¿Qué tan satisfecho te encuentras con la oferta académica de unidades de estudio? | E10: =LEN(D10) -> 81
A11: AC10 | B11: ¿Qué tan satisfecho te encuentras con el soporte brindado en temas de notas en Blackboard o SAP? | C11: AC10 | D11: ¿Qué tan satisfecho te encuentras con el soporte brindado en temas de notas en Blackboard o SAP? | E11: =LEN(D11) -> 96
A12: AC11 | B12: ¿Qué tan probable es que recomiendes tu programa académico con familiares y amigos? Ten en cuenta que 0 es "Totalmente improbable" y 10 es "Extremadamente probable" | C12: AC11 | D12: ¿Qué tan probable es que recomiendes tu programa académico con familiares y amigos? | E12: =LEN(D12) -> 83
A13: IES1 | B13: ¿Qué tan claro ha sido el concepto de 'sostenibilidad' en tu proceso de formación con la Universidad Ean? | C13: IES1 | D13: ¿Qué tan claro ha sido el concepto de sostenibilidad en tu proceso de formación con la Universidad Ean? | E13: =LEN(D13) -> 103
... A138: COMENT14 | B138: ¿Quieres destacar algo positivo de la Universidad Ean? ¿Crees que podemos mejorar en algo más? Déjanos saber algo que se nos haya pasado en esta encuesta. | C138: COMENT14 | D138: ¿Quieres destacar algo positivo de la Universidad Ean o sugerir mejoras adicionales? | E138: =LEN(D138) -> 84

Sheet Diccionario 2019
A1: Codigo_Area | B1: Area_PPT_2019 | C1: Pregunta | D1: Codigo_Area
A2: AC1 | B2: Academia | C2: ¿Qué tan satisfecho te encuentras con el programa más reciente que estás cursando en la Universidad Ean? | D2: AC1
A3: AC2 | B3: Academia | C3: ¿Qué tan cumplida ha sido la Universidad Ean en relación con el proceso de formación basado en competencias? | D3: AC2
A4: AC3 | B4: Academia | C4: En general, ¿cómo percibes la calidad docente de la Universidad Ean? | D4: AC3
A5: AC4 | B5: Academia | C5: ¿Qué tan fácil han hecho los docentes el proceso de aprendizaje en el que te encuentras? | D5: AC4
A6: AC5 | B6: Academia | C6: ¿Qué tan oportuna es la entrega de evaluaciones por parte de los docentes? | D6: AC5
A7: AC6 | B7: Academia | C7: ¿Qué tan competente es el personal de tu facultad? | D7: AC6
A8: AC7 | B8: Academia | C8: ¿Qué tan competentes son los responsables de tu programa académico (directores o coordinadores)? | D8: AC7
A9: AC8 | B9: Academia | C9: En general, ¿cómo calificas los mecanismos de interacción y comunicación de los colaboradores de tu facultad? | D9: AC8
A10: AC9 | B10: Academia | C10: ¿Qué tan satisfecho te encuentras con la oferta académica de unidades de estudio? | D10: AC9
A11: AC10 | B11: Academia | C11: ¿Qué tan satisfecho te encuentras con el soporte brindado en temas de notas en Blackboard o SAP? | D11: AC10
A12: AC11 | B12: Academia | C12: ¿Qué tan probable es que recomiendes tu programa académico con familiares y amigos? | D12: AC11
... A138: TIC4 | B138: TIC | C138: ¿Qué tan probable es que recomiendes el uso de los recursos tecnológicos de la Universidad Ean? | D138: TIC4

Sheet 2020
A1: Pregunta | B1: Codigo pregunta | C1: Pregunta abreviada
A2: ¿Qué tan satisfecho(a) te encuentras con la *calidad académica* del programa que cursas en la Universidad Ean? | B2: AC1 | C2: ¿Qué tan satisfecho(a) te encuentras con la calidad académica del programa que cursas en la Universidad Ean?
A3: ¿Qué tan cumplida ha sido la Universidad Ean respecto a la promesa de valor académica ofrecida? | B3: AC2 | C3: ¿Qué tan cumplida ha sido la Universidad Ean respecto a la promesa de valor académica ofrecida?
A4: En general, ¿Cómo percibes la calidad de los docentes de la Universidad Ean? | B4: AC3 | C4: En general, ¿Cómo percibes la calidad de los docentes de la Universidad Ean?
A5: ¿Qué tan oportuna es la entrega de calificaciones por parte de los docentes? | B5: AC4 | C5: ¿Qué tan oportuna es la entrega de calificaciones por parte de los docentes?
A6: ¿Qué tan cercanos percibes a los responsables de tu programa académico (decano(a), director(a) o coordinador(a)? | B6: AC5 | C6: ¿Qué tan cercanos percibes a los responsables de tu programa académico (decano(a), director(a) o coordinador(a)?
A7: La Unidad Académica Administrativa es el área en donde te brindan soporte sobre la programación académica, asesorías académicas, inscripción de unidades de estudio, actualizaciones de malla, procesos de homologación interna y externa, así como los reintegros. En general *¿Cómo calificas el soporte administrativo que brinda la Unidad Académica Administrativa?* | B7: AC6 | C7: En general ¿Cómo calificas el soporte administrativo que brinda la Unidad Académica Administrativa?
A8: ¿Cómo percibes la *atención y el servicio* por parte de los colaboradores de la Unidad Académica Administrativa? | B8: AC7 | C8: ¿Cómo percibes la atención y el servicio por parte de los colaboradores de la Unidad Académica Administrativa?
A9: Si eres estudiante presencial ¿Cómo evalúas el modelo PAT implementado durante la pandemia? | B9: AC8 | C9: Si eres estudiante presencial ¿Cómo evalúas el modelo PAT implementado durante la pandemia?
A10: ¿Consideras que la Universidad Ean te ha brindado el acompañamiento y soporte necesario para dar continuidad a tus actividades académicas durante la pandemia? | B10: AC9 | C10: ¿Consideras que la Universidad Ean te ha brindado el acompañamiento y soporte necesario para dar continuidad a tus actividades académicas durante la pandemia?
A11: ¿Qué tan probable es que recomiendes tu programa académico con familiares y amigos? Ten en cuenta que 0 es "Totalmente improbable" y 10 es "Extremadamente probable" | B11: AC10 | C11: ¿Qué tan probable es que recomiendes tu programa académico con familiares y amigos?
A12: ¿Conoces los servicios y beneficios que dispone el *Instituto de Emprendimiento Sostenible* para todos sus estudiantes? | B12: IES1 | C12: ¿Conoces los servicios y beneficios que dispone el Instituto de Emprendimiento Sostenible para todos sus estudiantes?
... A121: ¿Quieres destacar algo positivo de la Universidad Ean? ¿Crees que podemos mejorar en algún aspecto adicional? | B121: INST4 | C121: ¿Quieres destacar algo positivo de la Universidad Ean? ¿Crees que podemos mejorar en algún aspecto adicional?

Sheet Diccionario 2020
A1: Codigo_Area | B1: Nombre area | C1: Pegunta | D1: Codigo_Area
A2: AC1 | B2: Academia | C2: ¿Qué tan satisfecho(a) te encuentras con la calidad académica del programa que cursas en la Universidad Ean? | D2: AC1
A3: AC2 | B3: Academia | C3: ¿Qué tan cumplida ha sido la Universidad Ean respecto a la promesa de valor académica ofrecida? | D3: AC2
A4: AC3 | B4: Academia | C4: En general, ¿Cómo percibes la calidad de los docentes de la Universidad Ean? | D4: AC3
A5: AC4 | B5: Academia | C5: ¿Qué tan oportuna es la entrega de calificaciones por parte de los docentes? | D5: AC4
A6: AC5 | B6: Academia | C6: ¿Qué tan cercanos percibes a los responsables de tu programa académico (decano(a), director(a) o coordinador(a)? | D6: AC5
A7: AC6 | B7: Academia | C7: En general ¿Cómo calificas el soporte administrativo que brinda la Unidad Académica Administrativa? | D7: AC6
A8: AC7 | B8: Academia | C8: ¿Cómo percibes la atención y el servicio por parte de los colaboradores de la Unidad Académica Administrativa? | D8: AC7
A9: AC8 | B9: Academia | C9: Si eres estudiante presencial ¿Cómo evalúas el modelo PAT implementado durante la pandemia? | D9: AC8
A10: AC9 | B10: Academia | C10: ¿Consideras que la Universidad Ean te ha brindado el acompañamiento y soporte necesario para dar continuidad a tus actividades académicas durante la pandemia? | D10: AC9
A11: AC10 | B11: Academia | C11: ¿Qué tan probable es que recomiendes tu programa académico con familiares y amigos? | D11: AC10
A12: APF1 | B12: Apoyo financiero y tesorería | C12: ¿Conoces los convenios y opciones de financiación dispuestos por la Universidad para la financiación de matrícula? | D12: APF1
... A121: TIC6 | B121: TIC | C121: ¿Qué tan probable es que recomiendes el uso de recursos tecnológicos de la Universidad Ean con tus compañeros? | D121: TIC6

Sheet 2021
A1: Pregunta Original | B1: Codigo Pregunta | C1: Pregunta Abreviada
A2: Plan de estudios de tu programa | B2: AC1 | C2: Plan de estudios de tu programa
A3: Las competencias propuestas en las unidades cursadas hasta el momento | B3: AC2 | C3: Las competencias propuestas en las unidades cursadas hasta el momento
A4: ¿Qué tan cumplida ha sido la Universidad Ean respecto a la promesa de valor académica ofrecida por el programa que cursas actualmente? | B4: AC3 | C4: ¿Qué tan cumplida ha sido la Universidad Ean respecto a la promesa de valor académica ofrecida por el programa que cursas actualmente?
A5: Conocimiento disciplinar | B5: AC4 | C5: Conocimiento disciplinar
A6: Competencias para la enseñanza y la formación | B6: AC5 | C6: Competencias para la enseñanza y la formación
A7: Cumplimiento del Syllabus y plan de estudios del programa | B7: AC6 | C7: Cumplimiento del Syllabus y plan de estudios del programa
A8: Evaluación y acompañamiento del proceso de aprendizaje | B8: AC7 | C8: Evaluación y acompañamiento del proceso de aprendizaje
A9: Entrega de calificaciones y feedback | B9: AC8 | C9: Entrega de calificaciones y feedback
A10: Decano(a) | B10: AC9 | C10: Decano(a)
A11: Director (a) o Coordinador (a) | B11: AC10 | C11: Director (a) o Coordinador (a)
A12: En general ¿cómo calificas el soporte que presta el equipo de la Unidad Académico administrativa. | B12: AC11 | C12: En general ¿cómo calificas el soporte que presta el equipo de la Unidad Académico administrativa.
... A167: En una escala de 0 a 10 ¿Qué tan probable es que recomiendes los servicios y la atención que te brindamos en la Universidad Ean? | B167: INST7 | C167: En una escala de 0 a 10 ¿Qué tan probable es que recomiendes los servicios y la atención que te brindamos en la Universidad Ean?

Sheet Diccionario 2021
A1: Codigo_Area | B1: Area_PPT_2021 | C1: Item
A2: AC1 | B2: Academia | C2: Plan de estudios de tu programa | D2: AC1
A3: AC2 | B3: Academia | C3: Las competencias propuestas en las unidades cursadas hasta el momento | D3: AC2
A4: AC3 | B4: Academia | C4: ¿Qué tan cumplida ha sido la Universidad Ean respecto a la promesa de valor académica ofrecida por el programa que cursas actualmente? | D4: AC3
A5: AC4 | B5: Academia | C5: Conocimiento disciplinar | D5: AC4
A6: AC5 | B6: Academia | C6: Competencias para la enseñanza y la formación | D6: AC5
A7: AC6 | B7: Academia | C7: Cumplimiento del Syllabus y plan de estudios del programa | D7: AC6
A8: AC7 | B8: Academia | C8: Evaluación y acompañamiento del proceso de aprendizaje | D8: AC7
A9: AC8 | B9: Academia | C9: Entrega de calificaciones y feedback | D9: AC8
A10: AC9 | B10: Academia | C10: Decano(a) | D10: AC9
A11: AC10 | B11: Academia | C11: Director (a) o Coordinador (a) | D11: AC10
A12: AC11 | B12: Academia | C12: En general ¿cómo calificas el soporte que presta el equipo de la Unidad Académico administrativa. | D12: AC11
A13: AC12 | B13: Academia | C13: En general ¿Cómo calificas el soporte administrativo que brindan los asistentes de tu Facultad? | D13: AC12
... A167: TIC9 | B167: TIC | C167: Tecnología | D167: TIC9

Sheet 2022
A1: Pregunta Completa | B1: Codigo | C1: Pregunta Abreviada
A2: Plan de estudios de tu programa | B2: AC1 | C2: Plan de estudios de tu programa
A3: Las competencias propuestas en las unidades cursadas hasta el momento | B3: AC2 | C3: Las competencias propuestas en las unidades cursadas hasta el momento
A4: ¿Que tan cumplida ha sido la Universidad Ean respecto a la promesa de valor academica ofrecida por el programa que cursas actualmente | B4: AC3 | C4: ¿Que tan cumplida ha sido la Universidad Ean respecto a la promesa de valor academica ofrecida por el programa que cursas actualmente
A5: Conocimiento disciplinar | B5: AC4 | C5: Conocimiento disciplinar
A6: Competencias para la ensenanza y la formacion | B6: AC5 | C6: Competencias para la ensenanza y la formacion
A7: Cumplimiento del Syllabus y plan de estudios del programa | B7: AC6 | C7: Cumplimiento del Syllabus y plan de estudios del programa
A8: Evaluacion y acompanamiento del proceso de aprendizaje | B8: AC7 | C8: Evaluacion y acompanamiento del proceso de aprendizaje
A9: Entrega de calificaciones y feedback | B9: AC8 | C9: Entrega de calificaciones y feedback
A10: Aulas Virtuales | B10: MD1 | C10: Aulas Virtuales
A11: Decano | B11: AC9 | C11: Decano
A12: Director de Programa | B12: AC10 | C12: Director de Programa
... A161: En una escala de 0 a 10 ¿Que tan probable es que recomiendes los servicios y la atencion que te brindamos en la Universidad Ean | B161: INST1 | C161: En una escala de 0 a 10 ¿Que tan probable es que recomiendes los servicios y la atencion que te brindamos en la Universidad Ean

Sheet Diccionario 2022
A1: Codigo_Area | B1: Area_PPT_2022 | C1: Item
A2: AC1 | B2: Academia | C2: Plan de estudios de tu programa | D2: AC1
A3: AC2 | B3: Academia | C3: Las competencias propuestas en las unidades cursadas hasta el momento | D3: AC2
A4: AC3 | B4: Academia | C4: ¿Que tan cumplida ha sido la Universidad Ean respecto a la promesa de valor academica ofrecida por el programa que cursas actualmente | D4: AC3
A5: AC4 | B5: Academia | C5: Conocimiento disciplinar | D5: AC4
A6: AC5 | B6: Academia | C6: Competencias para la ensenanza y la formacion | D6: AC5
A7: AC6 | B7: Academia | C7: Cumplimiento del Syllabus y plan de estudios del programa | D7: AC6
A8: AC7 | B8: Academia | C8: Evaluacion y acompanamiento del proceso de aprendizaje | D8: AC7
A9: AC8 | B9: Academia | C9: Entrega de calificaciones y feedback | D9: AC8
A10: AC9 | B10: Academia | C10: Decano | D10: AC9
A11: AC10 | B11: Academia | C11: Director de Programa | D11: AC10
A12: AC11 | B12: Academia | C12: Coordinador Unidades de Estudio Transversales | D12: AC11
A13: AC12 | B13: Academia | C13: En general ¿Que tan satisfecho te encuentras con la atencion y el servicio recibido de manera presencial y a traves de las salas teams por parte del equipo de la Unidad Academico Administrativa | D13: AC12
... A161: TIC11 | B161: TIC | C161: Tecnologia | D161: TIC11

Sheet 2023
A1: Pregunta Completa | B1: Codigo | C1: Pregunta Abreviada
A2: Plan de estudios de tu programa | B2: =VLOOKUP(A2,'Diccionario 2023'!$C$2:$H$219,6,0) -> ACA1 | C2: Plan de estudios de tu programa
A3: Pertinencia de los conocimientos adquiridos en las clases | B3: =VLOOKUP(A3,'Diccionario 2023'!$C$2:$H$219,6,0) -> ACA2 | C3: Pertinencia de los conocimientos adquiridos en las clases
A4: Contribución del programa en tu proceso formativo | B4: =VLOOKUP(A4,'Diccionario 2023'!$C$2:$H$219,6,0) -> ACA3 | C4: Contribución del programa en tu proceso formativo
A5: ¿Qué tan cumplida ha sido la Universidad Ean respecto a la promesa de valor académica ofrecida por el programa que cursas actualmente? | B5: =VLOOKUP(A5,'Diccionario 2023'!$C$2:$H$219,6,0) -> ACA4 | C5: ¿Qué tan cumplida ha sido la Universidad Ean respecto a la promesa de valor académica ofrecida por el programa que cursas actualmente?
A6: Conforme al avance de tu programa académico: | B6: =VLOOKUP(A6,'Diccionario 2023'!$C$2:$H$219,6,0) -> ACA5 | C6: Conforme al avance de tu programa académico:
A7: Conocimiento disciplinar | B7: =VLOOKUP(A7,'Diccionario 2023'!$C$2:$H$219,6,0) -> ACA6 | C7: Conocimiento disciplinar
A8: Competencias para la enseñanza y la formación | B8: =VLOOKUP(A8,'Diccionario 2023'!$C$2:$H$219,6,0) -> ACA7 | C8: Competencias para la enseñanza y la formación
A9: Cumplimiento del syllabus y plan de estudios del programa | B9: =VLOOKUP(A9,'Diccionario 2023'!$C$2:$H$219,6,0) -> ACA8 | C9: Cumplimiento del syllabus y plan de estudios del programa
A10: Evaluación y acompañamiento del proceso de aprendizaje | B10: =VLOOKUP(A10,'Diccionario 2023'!$C$2:$H$219,6,0) -> ACA9 | C10: Evaluación y acompañamiento del proceso de aprendizaje
A11: Entrega de calificaciones y retroalimentación | B11: =VLOOKUP(A11,'Diccionario 2023'!$C$2:$H$219,6,0) -> ACA10 | C11: Entrega de calificaciones y retroalimentación
A12: Calidad humana | B12: =VLOOKUP(A12,'Diccionario 2023'!$C$2:$H$219,6,0) -> ACA11 | C12: Calidad humana
A13: Compromiso | B13: =VLOOKUP(A13,'Diccionario 2023'!$C$2:$H$219,6,0) -> ACA12 | C13: Compromiso
... A17: Sala Teams unidad academica | B17: =VLOOKUP(A17,'Diccionario 2023'!$C$2:$H$219,6,0) -> ACA16 | C17: Sala Teams unidad academica
A18: Atención presencial unidad academica | B18: ACA17 | C18: Atención presencial
A19: En general, ¿qué tan satisfecho(a) te encuentras con la atención y el servicio brindado por parte de las *asistentes de tu facultad*? | B19: =VLOOKUP(A19,'Diccionario 2023'!$C$2:$H$219,6,0) -> ACA18 | C19: En general, ¿qué tan satisfecho(a) te encuentras con la atención y el servicio brindado por parte de las *asistentes de tu facultad*?
A20: Sala Teams | B20: =VLOOKUP(A20,'Diccionario 2023'!$C$2:$H$219,6,0) -> ACA19 | C20: Sala Teams
A21: Atención presencial | B21: ACA20 | C21: Atención presencial
A22: Atención por correo electrónico | B22: =VLOOKUP(A22,'Diccionario 2023'!$C$2:$H$219,6,0) -> ACA21 | C22: Atención por correo electrónico
A23: Atención presencial | B23: ACA22 | C23: Atención presencial
A24: Atención por correo electrónico | B24: ACA23 | C24: Atención por correo electrónico
A25: Atención presencial | B25: ACA24 | C25: Atención presencial
A26: Disponibilidad y funcionamiento de los equipos | B26: ACA25 | C26: Disponibilidad y funcionamiento de los equipos
A27: Disponibilidad de materiales y/o reactivos | B27: =VLOOKUP(A27,'Diccionario 2023'!$C$2:$H$219,6,0) -> ACA26 | C27: Disponibilidad de materiales y/o reactivos
A28: Instalaciones | B28: =VLOOKUP(A28,'Diccionario 2023'!$C$2:$H$219,6,0) -> ACA27 | C28: Instalaciones
A29: Higiene y limpieza las Instalaciones y Equipos | B29: =VLOOKUP(A29,'Diccionario 2023'!$C$2:$H$219,6,0) -> ACA28 | C29: Higiene y limpieza las Instalaciones y Equipos
A30: ¿Qué tan probable es que recomiendes tu *programa académico* con familiares y amigos? | B30: =VLOOKUP(A30,'Diccionario 2023'!$C$2:$H$219,6,0) -> ACA29 | C30: ¿Qué tan probable es que recomiendes tu *programa académico* con familiares y amigos?
A31: ¿Qué tan probable es que en el futuro, vuelvas a estudiar un programa académico en la Universidad Ean? | B31: =VLOOKUP(A31,'Diccionario 2023'!$C$2:$H$219,6,0) -> ACA30 | C31: ¿Qué tan probable es que en el futuro, vuelvas a estudiar un programa académico en la Universidad Ean?
A32: ¿Conoces los servicios y beneficios que dispone *Ean Impacta* para todos sus estudiantes? | B32: =VLOOKUP(A32,'Diccionario 2023'!$C$2:$H$219,6,0) -> IMP1 | C32: ¿Conoces los servicios y beneficios que dispone *Ean Impacta* para todos sus estudiantes?
A33: ¿Qué tanto te ha influenciado la filosofía del emprendimiento sostenible de la Universidad Ean? | B33: =VLOOKUP(A33,'Diccionario 2023'!$C$2:$H$219,6,0) -> IMP2 | C33: ¿Qué tanto te ha influenciado la filosofía del emprendimiento sostenible de la Universidad Ean?
A34: Calidad académica | B34: =VLOOKUP(A34,'Diccionario 2023'!$C$2:$H$219,6,0) -> IMP3 | C34: Calidad académica
A35: Calidad docente | B35: =VLOOKUP(A35,'Diccionario 2023'!$C$2:$H$219,6,0) -> IMP4 | C35: Calidad docente
A36: Diversidad e inclusión | B36: =VLOOKUP(A36,'Diccionario 2023'!$C$2:$H$219,6,0) -> IMP5 | C36: Diversidad e inclusión
A37: Emprendimiento | B37: =VLOOKUP(A37,'Diccionario 2023'!$C$2:$H$219,6,0) -> IMP6 | C37: Emprendimiento
A38: Ética y valores | B38: =VLOOKUP(A38,'Diccionario 2023'!$C$2:$H$219,6,0) -> IMP7 | C38: Ética y valores
... A45: ¿En qué tipo de acciones te gustaría participar junto a Ean Sostenibilidad? | B45: =VLOOKUP(A45,'Diccionario 2023'!$C$2:$H$219,6,0) -> SOS2 | C45: ¿En qué tipo de acciones te gustaría participar junto a Ean Sostenibilidad?
A46: Other | B46: SOS3 | C46: Other
A47: Asesoría en referencias, normas APA y trabajos de grado | B47: =VLOOKUP(A47,'Diccionario 2023'!$C$2:$H$219,6,0) -> BIB1 | C47: Asesoría en referencias, normas APA y trabajos de grado
A48: Búsqueda de información | B48: =VLOOKUP(A48,'Diccionario 2023'!$C$2:$H$219,6,0) -> BIB2 | C48: Búsqueda de información
A49: Préstamo de libros | B49: =VLOOKUP(A49,'Diccionario 2023'!$C$2:$H$219,6,0) -> BIB3 | C49: Préstamo de libros
...

Sheet Diccionario 2023
A1: orden | B1: Sigla | C1: pregunta | D1: area_analisis | F1: codigo_area
A2: 1 | B2: ACA1 | C2: Plan de estudios de tu programa | D2: Academia | E2: AC1 | F2: ACA | G2: 1 | H2: ACA1
A3: 2 | B3: ACA2 | C3: Pertinencia de los conocimientos adquiridos en las clases | D3: Academia | E3: AC1 | F3: ACA | G3: 2 | H3: ACA2
A4: 3 | B4: ACA3 | C4: Contribución del programa en tu proceso formativo | D4: Academia | E4: AC1 | F4: ACA | G4: 3 | H4: ACA3
A5: 4 | B5: ACA4 | C5: ¿Qué tan cumplida ha sido la Universidad Ean respecto a la promesa de valor académica ofrecida por el programa que cursas actualmente? | D5: Academia | E5: AC1 | F5: ACA | G5: 4 | H5: ACA4
A6: 5 | B6: ACA5 | C6: Conforme al avance de tu programa académico: | D6: Academia | E6: AC1 | F6: ACA | G6: 5 | H6: ACA5
A7: 6 | B7: ACA6 | C7: Conocimiento disciplinar | D7: Academia | E7: AC1 | F7: ACA | G7: 6 | H7: ACA6
A8: 7 | B8: ACA7 | C8: Competencias para la enseñanza y la formación | D8: Academia | E8: AC1 | F8: ACA | G8: 7 | H8: ACA7
A9: 8 | B9: ACA8 | C9: Cumplimiento del syllabus y plan de estudios del programa | D9: Academia | E9: AC1 | F9: ACA | G9: 8 | H9: ACA8
A10: 9 | B10: ACA9 | C10: Evaluación y acompañamiento del proceso de aprendizaje | D10: Academia | E10: AC1 | F10: ACA | G10: 9 | H10: ACA9
A11: 10 | B11: ACA10 | C11: Entrega de calificaciones y retroalimentación | D11: Academia | E11: AC1 | F11: ACA | G11: 10 | H11: ACA10
A12: 11 | B12: ACA11 | C12: Calidad humana | D12: Academia | E12: AC1 | F12: ACA | G12: 11 | H12: ACA11
A13: 12 | B13: ACA12 | C13: Compromiso | D13: Academia | E13: AC1 | F13: ACA | G13: 12 | H13: ACA12
... A219: 218 | B219: INSTI3 | C219: En una escala de 0 a 10 ¿Qué tan probable es que recomiendes los servicios y la atención que te brindamos en la Universidad Ean? | D219: Institucional | E219: INST1 | F219: INSTI | G219: 3 | H219: INSTI3

Sheet 2024
A1: Pregunta Completa | B1: Codigo | C1: Pregunta Abreviada
A2: _Plan de estudios de tu programa_ | B2: ACA1 | C2: =VLOOKUP(A2,'Diccionario 2024'!$B$2:$D$230,3,0) -> Plan de estudios de tu programa
A3: _Pertinencia de los conocimientos adquiridos en las clases_ | B3: ACA2 | C3: =VLOOKUP(A3,'Diccionario 2024'!$B$2:$D$230,3,0) -> Pertinencia de los conocimientos adquiridos en las clases
A4: _Contribución del programa en tu proceso formativo_ | B4: ACA3 | C4: =VLOOKUP(A4,'Diccionario 2024'!$B$2:$D$230,3,0) -> Contribución del programa en tu proceso formativo
A5: ¿Qué tan cumplida ha sido la Universidad Ean respecto a la promesa de valor académica ofrecida por el programa que cursas actualmente? | B5: ACA4 | C5: =VLOOKUP(A5,'Diccionario 2024'!$B$2:$D$230,3,0) -> ¿Qué tan cumplida ha sido la Universidad Ean respecto a la promesa de valor académica ofrecida por el programa que cursas actualmente?
A6: Conforme al avance de tu programa académico: | B6: ACA5 | C6: =VLOOKUP(A6,'Diccionario 2024'!$B$2:$D$230,3,0) -> Conforme al avance de tu programa académico:
A7: _Conocimiento disciplinar_ | B7: ACA6 | C7: =VLOOKUP(A7,'Diccionario 2024'!$B$2:$D$230,3,0) -> Conocimiento disciplinar
A8: _Competencias para la enseñanza y la formación_ | B8: ACA7 | C8: =VLOOKUP(A8,'Diccionario 2024'!$B$2:$D$230,3,0) -> Competencias para la enseñanza y la formación
A9: _Cumplimiento del syllabus y plan de estudios del programa_ | B9: ACA8 | C9: =VLOOKUP(A9,'Diccionario 2024'!$B$2:$D$230,3,0) -> Cumplimiento del syllabus y plan de estudios del programa
A10: _Evaluación y acompañamiento del proceso de aprendizaje_ | B10: ACA9 | C10: =VLOOKUP(A10,'Diccionario 2024'!$B$2:$D$230,3,0) -> Evaluación y acompañamiento del proceso de aprendizaje
A11: _Entrega de calificaciones y retroalimentación_ | B11: ACA10 | C11: =VLOOKUP(A11,'Diccionario 2024'!$B$2:$D$230,3,0) -> Entrega de calificaciones y retroalimentación
A12: _Calidad humana_ | B12: ACA11 | C12: =VLOOKUP(A12,'Diccionario 2024'!$B$2:$D$230,3,0) -> Calidad humana
A13: _Compromiso_ | B13: ACA12 | C13: =VLOOKUP(A13,'Diccionario 2024'!$B$2:$D$230,3,0) -> Compromiso
... A19: Mesa de Servicio | B19: EXP3 | C19: =VLOOKUP(A19,'Diccionario 2024'!$B$2:$D$230,3,0) -> Mesa de Servicio
A20: En general, ¿qué tan satisfecho/satisfecha estás con la asignación y entrega de material de estudio a través de *Materiales VAC *por parte de Unidad Académica Administrativa? (Pearson - Inglés/Ciencias Básicas, BBP – Contaduría, Cognos - Portugués Libro, Rosetta-Portugués vrt, Al Dente – Italiano, Cosmopolite – Francés, DaF im Unternehmen - Alemán) | B20: ACA16 | C20: Satisfacción entrega material VAC
A21: En general, ¿qué tan satisfecho/satisfecha te encuentras con la atención y el servicio brindado por parte de las *asistentes de tu facultad*? | B21: ACA17 | C21: =VLOOKUP(A21,'Diccionario 2024'!$B$2:$D$230,3,0) -> Satisfacción asistentes facultad
A22: Meli Turno (Virtual) | B22: EXP1 | C22: =VLOOKUP(A22,'Diccionario 2024'!$B$2:$D$230,3,0) -> Meli Turno (Virtual)
A23: Atención Ean a tu lado (Presencial). | B23: EXP2 | C23: =VLOOKUP(A23,'Diccionario 2024'!$B$2:$D$230,3,0) -> Atención Ean a tu lado (Presencial)
A24: Mesa de Servicio | B24: EXP3 | C24: =VLOOKUP(A24,'Diccionario 2024'!$B$2:$D$230,3,0) -> Mesa de Servicio
A25: Atención por correo electrónico | B25: COM1 | C25: =VLOOKUP(A25,'Diccionario 2024'!$B$2:$D$230,3,0) -> Atención por correo electrónico
A26: Atención presencial (Tercer Piso Legacy) | B26: COM2 | C26: =VLOOKUP(A26,'Diccionario 2024'!$B$2:$D$230,3,0) -> Atención presencial (Tercer Piso Legacy)
A27: Atención por correo electrónico | B27: COM1 | C27: =VLOOKUP(A27,'Diccionario 2024'!$B$2:$D$230,3,0) -> Atención por correo electrónico
A28: Atención presencial (Tercer Piso Legacy). | B28: COM4 | C28: =VLOOKUP(A28,'Diccionario 2024'!$B$2:$D$230,3,0) -> Atención presencial (Tercer Piso Legacy)
A29: _Disponibilidad y funcionamiento de los equipos _ | B29: FAB1 | C29: =VLOOKUP(A29,'Diccionario 2024'!$B$2:$D$230,3,0) -> Disponibilidad y funcionamiento de los equipos
A30: _Disponibilidad de materiales y/o reactivos_ | B30: FAB2 | C30: =VLOOKUP(A30,'Diccionario 2024'!$B$2:$D$230,3,0) -> Disponibilidad de materiales y/o reactivos
A31: _Instalaciones_ | B31: PLF1 | C31: =VLOOKUP(A31,'Diccionario 2024'!$B$2:$D$230,3,0) -> Instalaciones
A32: _Higiene y limpieza las Instalaciones y Equipos_ | B32: PLF2 | C32: =VLOOKUP(A32,'Diccionario 2024'!$B$2:$D$230,3,0) -> Higiene y limpieza instalaciones y equipos
... A225: Si la respuesta anterior es que tienes hijos de 5 años o menos, ¿usarías un futuro servicio de cuidado infantil mientras vas a clase en la Ean? | B225: INSTI4 | C225: =VLOOKUP(A225,'Diccionario 2024'!$B$2:$D$230,3,0) -> Servicio cuidado infantil
A226: Entendiendo la *inclusión *como un principio que permite comprender a la comunidad estudiantil, reconocer derechos, promover el respeto por la diferencia y valorar a la persona en su individualidad, ¿qué tan satisfecho o satisfecha te sientes con el carácter inclusivo que promueve la institución dentro del ambiente universitario? | B226: EXP40 | C226: Satisfacción inclusión universidad
A227: ¿Qué tan satisfecho/satisfecha te encuentras con el servicio y atención que te brinda el *equipo de recepción* de la universidad? | B227: EXP41 | C227: =VLOOKUP(A227,'Diccionario 2024'!$B$2:$D$230,3,0) -> Satisfacción atención recepción
A228: ¿Quieres destacar algo positivo de la *Universidad Ean*? | B228: INSTI5 | C228: =VLOOKUP(A228,'Diccionario 2024'!$B$2:$D$230,3,0) -> Aspecto positivo universidad
A229: ¿Tienes alguna sugerencia en la que podríamos mejorar? | B229: INSTI6 | C229: =VLOOKUP(A229,'Diccionario 2024'!$B$2:$D$230,3,0) -> Sugerencias mejora universidad
A230: En una escala de 0 a 10, ¿qué tan probable es que recomiendes los servicios y la atención que te brindamos en la *Universidad Ean*? | B230: INSTI7 | C230: =VLOOKUP(A230,'Diccionario 2024'!$B$2:$D$230,3,0) -> Recomendación servicios universidad

Sheet Diccionario 2024
A1: Item | B1: Pregunta larga | C1: Codigo_Area | D1: Pregunta Abreviada | E1: Area_PPT_2024 | F1: Codigo pregunta | G1: Area_PPT_2024
A2: 1 | B2: _Plan de estudios de tu programa_ | C2: =VLOOKUP(A2,Hoja3!$A$2:$D$230,4,0) -> ACA | D2: Plan de estudios de tu programa | E2: Academia | F2: ACA1 | G2: Academia
A3: 2 | B3: _Pertinencia de los conocimientos adquiridos en las clases_ | C3: =VLOOKUP(A3,Hoja3!$A$2:$D$230,4,0) -> ACA | D3: Pertinencia de los conocimientos adquiridos en las clases | E3: Academia | F3: ACA2 | G3: Academia
A4: 3 | B4: _Contribución del programa en tu proceso formativo_ | C4: =VLOOKUP(A4,Hoja3!$A$2:$D$230,4,0) -> ACA | D4: Contribución del programa en tu proceso formativo | E4: Academia | F4: ACA3 | G4: Academia
A5: 4 | B5: ¿Qué tan cumplida ha sido la Universidad Ean respecto a la promesa de valor académica ofrecida por el programa que cursas actualmente? | C5: =VLOOKUP(A5,Hoja3!$A$2:$D$230,4,0) -> ACA | D5: ¿Qué tan cumplida ha sido la Universidad Ean respecto a la promesa de valor académica ofrecida por el programa que cursas actualmente? | E5: Academia | F5: ACA4 | G5: Academia
A6: 5 | B6: Conforme al avance de tu programa académico: | C6: =VLOOKUP(A6,Hoja3!$A$2:$D$230,4,0) -> ACA | D6: Conforme al avance de tu programa académico: | E6: Academia | F6: ACA5 | G6: Academia
A7: 6 | B7: _Conocimiento disciplinar_ | C7: =VLOOKUP(A7,Hoja3!$A$2:$D$230,4,0) -> ACA | D7: Conocimiento disciplinar | E7: Academia | F7: ACA6 | G7: Academia
A8: 7 | B8: _Competencias para la enseñanza y la formación_ | C8: =VLOOKUP(A8,Hoja3!$A$2:$D$230,4,0) -> ACA | D8: Competencias para la enseñanza y la formación | E8: Academia | F8: ACA7 | G8: Academia
A9: 8 | B9: _Cumplimiento del syllabus y plan de estudios del programa_ | C9: =VLOOKUP(A9,Hoja3!$A$2:$D$230,4,0) -> ACA | D9: Cumplimiento del syllabus y plan de estudios del programa | E9: Academia | F9: ACA8 | G9: Academia
A10: 9 | B10: _Evaluación y acompañamiento del proceso de aprendizaje_ | C10: =VLOOKUP(A10,Hoja3!$A$2:$D$230,4,0) -> ACA | D10: Evaluación y acompañamiento del proceso de aprendizaje | E10: Academia | F10: ACA9 | G10: Academia
A11: 10 | B11: _Entrega de calificaciones y retroalimentación_ | C11: =VLOOKUP(A11,Hoja3!$A$2:$D$230,4,0) -> ACA | D11: Entrega de calificaciones y retroalimentación | E11: Academia | F11: ACA10 | G11: Academia
A12: 11 | B12: _Calidad humana_ | C12: =VLOOKUP(A12,Hoja3!$A$2:$D$230,4,0) -> ACA | D12: Calidad humana | E12: Academia | F12: ACA11 | G12: Academia
A13: 12 | B13: _Compromiso_ | C13: =VLOOKUP(A13,Hoja3!$A$2:$D$230,4,0) -> ACA | D13: Compromiso | E13: Academia | F13: ACA12 | G13: Academia
... A230: 229 | B230: En una escala de 0 a 10, ¿qué tan probable es que recomiendes los servicios y la atención que te brindamos en la *Universidad Ean*? | C230: =VLOOKUP(A230,Hoja3!$A$2:$D$230,4,0) -> INSTI | D230: Recomendación servicios universidad | E230: Comentarios finales | F230: INSTI7 | G230: Comentarios finales

Sheet Hoja3
A1: item | B1: pregunta | C1: area | D1: sigla
A2: 1 | B2: Plan de estudios de tu programa | C2: Academia | D2: ACA
A3: 2 | B3: Pertinencia de los conocimientos adquiridos en las clases | C3: Academia | D3: ACA
A4: 3 | B4: Contribución del programa en tu proceso formativo | C4: Academia | D4: ACA
A5: 4 | B5: ¿Qué tan cumplida ha sido la Universidad Ean respecto a la promesa de valor académica ofrecida por el programa que cursas actualmente? | C5: Academia | D5: ACA
A6: 5 | B6: Conforme al avance de tu programa académico: | C6: Academia | D6: ACA
A7: 6 | B7: Conocimiento disciplinar | C7: Academia | D7: ACA
A8: 7 | B8: Competencias para la enseñanza y la formación | C8: Academia | D8: ACA
A9: 8 | B9: Cumplimiento del syllabus y plan de estudios del programa | C9: Academia | D9: ACA
A10: 9 | B10: Evaluación y acompañamiento del proceso de aprendizaje | C10: Academia | D10: ACA
A11: 10 | B11: Entrega de calificaciones y retroalimentación | C11: Academia | D11: ACA
A12: 11 | B12: Calidad humana | C12: Academia | D12: ACA
A13: 12 | B13: Compromiso | C13: Academia | D13: ACA
... A230: 229 | B230: Recomendación servicios universidad | C230: INSTI | D230: INSTI

Sheet Siglas Areas
A1: AREAS 2024 | B1: AREAS AÑOS ANTERIORES | C1: SIGLA | D1: AREAS 2024
A2: Academia | B2: Academia | C2: ACA | D2: Academia
A3: Ean Impacta | B3: Ean Impacta | C3: IMP | D3: Ean Impacta
A4: Ean Sostenibilidad | B4: Ean Sostenibilidad | C4: SOS | D4: Ean Sostenibilidad
A5: Biblioteca | B5: Biblioteca | C5: BIB | D5: Biblioteca
A6: Internacionalización | B6: Internacionalización | C6: INT | D6: Internacionalización
A7: Prácticas Profesionales | B7: Prácticas Profesionales | C7: PRA | D7: Prácticas Profesionales
A8: Plataforma y soporte | B8: Plataformas y soporte | C8: PLA | D8: Plataforma y soporte
A9: Registro Académico | B9: Registro Académico | C9: REG | D9: Registro Académico
A10: Apoyo y recursos financieros | B10: Apoyo y Recursos Financieros | C10: FIN | D10: Apoyo y recursos financieros
A11: Canales de atención | B11: Canales de comunicación | C11: COM | D11: Canales de atención
A12: Comunicaciones | B12: Canales de comunicación | C12: COM | D12: Comunicaciones
... A22: Comentarios finales | B22: Institucional | C22: INSTI | D22: Comentarios finales
C24: APF | D24: Apoyo y recursos financieros
