Workbook

Sheet BASE_COSTEO (2)
A1: Año | B1: Mes | C1: COMPLEJIDAD | D1: PROCEDIMIENTO | E1: CODIGO_CUPS | F1: TIEMPO_MINUTOS | G1: TIPO_REGISTRO | H1: CATEGORIA_COSTO | I1: ITEM | J1: CANTIDAD | K1: UNIDAD_MEDIDA | L1: COSTO_UNITARIO | M1: COSTO_TOTAL | N1: OBSERVACIONES
A2: 2026 | B2: Mayo | C2: Baja Complejidad | D2: Curación de BAJA COMPLEJIDAD | E2: 1965 | F2: 30 | G2: INSUMO | H2: INSUMO | I2: Guante examen talla M | J2: 4 | K2: UND | L2: 10948 | M2: 218.96 | N2: 2 PARES
A3: 2026 | B3: Mayo | C3: Baja Complejidad | D3: Curación de BAJA COMPLEJIDAD | E3: 1965 | F3: 30 | G3: INSUMO | H3: INSUMO | I3: Guante quirurgico esteril 7.0 | J3: 1 | K3: UND | L3: 1086.232 | M3: 1086.232 | N3: 1 PAR
A4: 2026 | B4: Mayo | C4: Baja Complejidad | D4: Curación de BAJA COMPLEJIDAD | E4: 1965 | F4: 30 | G4: INSUMO | H4: INSUMO | I4: Gasa esteril 7.5 X 7.5 sobre x 5 unid | J4: 4 | K4: UND | L4: 370 | M4: 1480
A5: 2026 | B5: Mayo | C5: Baja Complejidad | D5: Curación de BAJA COMPLEJIDAD | E5: 1965 | F5: 30 | G5: INSUMO | H5: INSUMO | I5: Solucion Salina 0.9% Bolsa 100 ml | J5: 1 | K5: UND | L5: 1965 | M5: 1965
A6: 2026 | B6: Mayo | C6: Baja Complejidad | D6: Curación de BAJA COMPLEJIDAD | E6: 1965 | F6: 30 | G6: INSUMO | H6: INSUMO | I6: Cinta adhesiva x 200cm Fixomull ( por centimetro) | J6: 1 | K6: UND | N6: 30 CM
A7: 2026 | B7: Mayo | C7: Baja Complejidad | D7: Curación de BAJA COMPLEJIDAD | E7: 1965 | F7: 30 | G7: INSUMO | H7: INSUMO | I7: Tapabocas Estandar 1405 | J7: 0.4 | K7: UND | L7: 135.66 | M7: 54.264
A8: 2026 | B8: Mayo | C8: Baja Complejidad | D8: Curación de BAJA COMPLEJIDAD | E8: 1965 | F8: 30 | G8: INSUMO | H8: INSUMO | I8: Bata Desechable con Manga No Esteril | J8: 2 | K8: UND | L8: 3808 | M8: 7616
A9: 2026 | B9: Mayo | C9: Baja Complejidad | D9: Curación de BAJA COMPLEJIDAD | E9: 1965 | F9: 30 | G9: INSUMO | H9: INSUMO | I9: Gorro Desechable Estandar Blanco | J9: 0.4 | K9: UND | L9: 111.86 | M9: 44.744
A10: 2026 | B10: Mayo | C10: Baja Complejidad | D10: Curación de BAJA COMPLEJIDAD | E10: 1965 | F10: 30 | G10: INSUMO | H10: INSUMO | I10: acido hipocloroso | J10: 2 | K10: UND
A11: 2026 | B11: Mayo | C11: Baja Complejidad | D11: Curación de BAJA COMPLEJIDAD | E11: 1965 | F11: 30 | G11: INSUMO | H11: INSUMO | I11: Toalla de Manos Pre-cortada Natural R7 | J11: 2 | K11: UND | L11: 17888.08 | M11: 357.7616
A12: 2026 | B12: Mayo | C12: Baja Complejidad | D12: Curación de BAJA COMPLEJIDAD | E12: 1965 | F12: 30 | G12: INSUMO | H12: INSUMO | I12: Hoja para bisturi 15 | J12: 1 | K12: UND | L12: 337.38379 | M12: 337.38379
A13: 2026 | B13: Mayo | C13: Baja Complejidad | D13: Curación de BAJA COMPLEJIDAD | E13: 1965 | F13: 30 | G13: INSUMO | H13: INSUMO | I13: Venda de algodon 6 x 5 | J13: 1 | K13: UND | L13: 1843.3333 | M13: 1843.3333
A14: 2026 | B14: Mayo | C14: Baja Complejidad | D14: Curación de BAJA COMPLEJIDAD | E14: 1965 | F14: 30 | G14: INSUMO | H14: INSUMO | I14: Venda elastica 6 x 5 | J14: 1 | K14: UND | L14: 2346 | M14: 2346
A15: 2026 | B15: Mayo | C15: Baja Complejidad | D15: Curación de BAJA COMPLEJIDAD | E15: 1965 | F15: 30 | G15: MANO_OBRA | H15: MANO_OBRA | I15: Enfermera | J15: 30 | K15: MINUTOS
A16: 2026 | B16: Mayo | C16: Baja Complejidad | D16: Curación de BAJA COMPLEJIDAD | E16: 1965 | F16: 30 | G16: MANO_OBRA | H16: MANO_OBRA | I16: Auxiliar enfermeria | J16: 30 | K16: MINUTOS
A17: 2026 | B17: Mayo | C17: Baja Complejidad | D17: Curación de BAJA COMPLEJIDAD | E17: 1965 | F17: 30 | G17: GASTO_ADMINISTRATIVO | H17: GASTO_ADMINISTRATIVO | I17: Gasto administrativo | J17: 30 | K17: MINUTOS | M17: 12657
A18: 2026 | B18: Mayo | C18: Baja Complejidad | D18: Curación de BAJA COMPLEJIDAD | E18: 360001 | G18: INSUMO | H18: INSUMO | I18: Granulox Hemoglobina Spray | K18: Unidad | M18: 893800
A19: 2026 | B19: Mayo | C19: Baja Complejidad | D19: Curación de BAJA COMPLEJIDAD | E19: 360102 | G19: INSUMO | H19: INSUMO | I19: Granudacyn Solución 1000 ml | K19: Unidad | M19: 251100
A20: 2026 | B20: Mayo | C20: Baja Complejidad | D20: Curación de BAJA COMPLEJIDAD | E20: 360104 | G20: INSUMO | H20: INSUMO | I20: Granudacyn Solución 1000 ml NPWT | K20: Unidad | M20: 261100
A21: 2026 | B21: Mayo | C21: Baja Complejidad | D21: Curación de BAJA COMPLEJIDAD | E21: 360100 | G21: INSUMO | H21: INSUMO | I21: Granudacyn Solución 250 ml Spray | K21: Unidad | M21: 80300
A22: 2026 | B22: Mayo | C22: Baja Complejidad | D22: Curación de BAJA COMPLEJIDAD | E22: 360150 | G22: INSUMO | H22: INSUMO | I22: Granudacyn Solución 50 ml Spray | K22: Unidad | M22: 76800
A23: 2026 | B23: Mayo | C23: Baja Complejidad | D23: Curación de BAJA COMPLEJIDAD | E23: 360101 | G23: INSUMO | H23: INSUMO | I23: Granudacyn Solución 500 ml | K23: Unidad | M23: 140600
A24: 2026 | B24: Mayo | C24: Baja Complejidad | D24: Curación de BAJA COMPLEJIDAD | E24: 360103 | G24: INSUMO | H24: INSUMO | I24: Granudacyn Solución 500 ml NPWT | K24: Unidad | M24: 150600
A25: 2026 | B25: Mayo | C25: Baja Complejidad | D25: Curación de BAJA COMPLEJIDAD | E25: 709900 | G25: INSUMO | H25: INSUMO | I25: Exufiber 5 x 5 cm | K25: Caja X 10 | M25: 13500
A26: 2026 | B26: Mayo | C26: Baja Complejidad | D26: Curación de BAJA COMPLEJIDAD | E26: 709902 | G26: INSUMO | H26: INSUMO | I26: Exufiber 10 x 12 cm | K26: Caja X 10 | M26: 28800
A27: 2026 | B27: Mayo | C27: Baja Complejidad | D27: Curación de BAJA COMPLEJIDAD | E27: 709903 | G27: INSUMO | H27: INSUMO | I27: Exufiber 15 x 15 cm | K27: Caja X 10 | M27: 63400
A28: 2026 | B28: Mayo | C28: Baja Complejidad | D28: Curación de BAJA COMPLEJIDAD | E28: 709909 | G28: INSUMO | H28: INSUMO | I28: Exufiber 2 x 45 cm | K28: Caja X 5 | M28: 38400
A29: 2026 | B29: Mayo | C29: Baja Complejidad | D29: Curación de BAJA COMPLEJIDAD | E29: 709904 | G29: INSUMO | H29: INSUMO | I29: Exufiber 20 x 30 cm | K29: Caja X 5 | M29: 169000
... A112: 2026 | B112: Mayo | C112: Baja Complejidad | D112: Curación de BAJA COMPLEJIDAD | E112: 2444 | G112: INSUMO | H112: INSUMO | I112: Tubifast 10m Violeta | K112: Unidad | M112: 200900
A113: 2026 | B113: Mayo | C113: Mediana Complejidad | D113: Curación de MEDIANA COMPLEJIDAD | E113: 26180 | F113: 45 | G113: INSUMO | H113: INSUMO | I113: Guante examen talla M | J113: 4 | K113: UND | L113: 10948 | M113: 43792
A114: 2026 | B114: Mayo | C114: Mediana Complejidad | D114: Curación de MEDIANA COMPLEJIDAD | E114: 26180 | F114: 45 | G114: INSUMO | H114: INSUMO | I114: Guante quirurgico esteril 7.0 | J114: 2 | K114: UND | L114: 1086.232 | M114: 2172.464
A115: 2026 | B115: Mayo | C115: Mediana Complejidad | D115: Curación de MEDIANA COMPLEJIDAD | E115: 26180 | F115: 45 | G115: INSUMO | H115: INSUMO | I115: Gasa esteril 7.5 X 7.5 sobre x 5 unid | J115: 6 | K115: UND | L115: 370 | M115: 2220
A116: 2026 | B116: Mayo | C116: Mediana Complejidad | D116: Curación de MEDIANA COMPLEJIDAD | E116: 26180 | F116: 45 | G116: INSUMO | H116: INSUMO | I116: Solucion Salina 0.9% Bolsa 100 ml | J116: 2 | K116: UND | L116: 1965 | M116: 3930
A117: 2026 | B117: Mayo | C117: Mediana Complejidad | D117: Curación de MEDIANA COMPLEJIDAD | E117: 26180 | F117: 45 | G117: INSUMO | H117: INSUMO | I117: Cinta adhesiva x 200cm Fixomull | J117: 1 | K117: UND | L117: 26180 | M117: 26180
A118: 2026 | B118: Mayo | C118: Mediana Complejidad | D118: Curación de MEDIANA COMPLEJIDAD | E118: 26180 | F118: 45 | G118: INSUMO | H118: INSUMO | I118: Tapabocas Estandar 1405 | J118: 0.4 | K118: UND | L118: 135.66 | M118: 54.264
A119: 2026 | B119: Mayo | C119: Mediana Complejidad | D119: Curación de MEDIANA COMPLEJIDAD | E119: 26180 | F119: 45 | G119: INSUMO | H119: INSUMO | I119: Bata Desechable con Manga No Esteril | J119: 2 | K119: UND | L119: 3808 | M119: 7616
A120: 2026 | B120: Mayo | C120: Mediana Complejidad | D120: Curación de MEDIANA COMPLEJIDAD | E120: 26180 | F120: 45 | G120: INSUMO | H120: INSUMO | I120: Gorro Desechable Estandar Blanco | J120: 0.4 | K120: UND | L120: 111.86 | M120: 44.744
A121: 2026 | B121: Mayo | C121: Mediana Complejidad | D121: Curación de MEDIANA COMPLEJIDAD | E121: 26180 | F121: 45 | G121: INSUMO | H121: INSUMO | I121: acido hipocloroso | J121: 2 | K121: UND
A122: 2026 | B122: Mayo | C122: Mediana Complejidad | D122: Curación de MEDIANA COMPLEJIDAD | E122: 26180 | F122: 45 | G122: INSUMO | H122: INSUMO | I122: Toalla de Manos Pre-cortada Natural R7 | J122: 2 | K122: UND | L122: 17888.08 | M122: 357.7616
...

Sheet DashBoard
C9: 💰 COSTO TOTAL A 6 MESES | E9: 💊 COSTO TOTAL INSUMOS POR MES | G9: 📊 COSTO PROMEDIO X COMPLEJIDAD | I9: 👷 COSTO CURACIÓN DIARIA | K9: 🏢 GASTOS ADMINISTRATIVOS POR MES | M9: ⏰ TIEMPO PROMEDIO
C10: =SUM(BASE_COSTEO!M2:M680) -> 1.1102312e+08 | E10: =SUMIF(BASE_COSTEO!$G$2:$G$680,"INSUMO",BASE_COSTEO!$M$2:$M$680)/6 -> 364946.57 | G10: =AVERAGE(BASE_COSTEO!M2:M680) -> 163509.76 | I10: =AVERAGEIF(BASE_COSTEO!$H$2:$H$680,"MANO_OBRA",BASE_COSTEO!$M$2:$M$680)/6 -> 178866.26 | K10: =SUMIF(BASE_COSTEO!$G$2:$G$680,"GASTO_ADMINISTRATIVO",BASE_COSTEO!$M$2:$M$680)/6 -> 2616433.2 | M10: =ROUND(AVERAGEIF(BASE_COSTEO!$K$2:$K$680,"MINUTOS",BASE_COSTEO!$J$2:$J$680),2) & " min" -> 48 min
F17: Etiquetas de fila | G17: Suma de COSTO_TOTAL | K17: Etiquetas de fila | L17: COSTO_TOTAL_
F18: Baja Complejidad | G18: 11294501 | K18: MANO_OBRA | L18: 67611446
F19: GASTO_ADMINISTRATIVO | G19: 15610000 | K19: INSUMO ALTA TECNOLOGIA | L19: 25523400
F20: Mediana Complejidad | G20: 29680186 | K20: GASTO_ADMINISTRATIVO | L20: 15698599
F21: Alta Complejidad | G21: 54438438 | K21: INSUMO | L21: 2189679.4
F22: Total general | G22: 1.1102312e+08 | K22: Total general | L22: 1.1102312e+08
C27: 💰 INGRESOS TOTALES A 6 MESES | E27: 💊 UTILIDAD TOTAL | G27: 📊 % MARGEN UTILIDAD | I27: 👷 PROCEDIMIENTO MAS RENTABLE | K27: 🏢 PROYECCIÓN MENSUAL | M27: ⏰ PUNTO EQUILIBRIO OPERACIONAL
C28: =SUM(BASE_COSTEO!$R$2:$R$680)+SUM(BASE_COSTEO!$V$2:$V$680)+SUM(BASE_COSTEO!$Z$2:$Z$680) -> 1.161278e+08 | E28: =(SUM(BASE_COSTEO!$R$2:$R$680)+SUM(BASE_COSTEO!$V$2:$V$680)+SUM(BASE_COSTEO!$Z$2:$Z$680))-SUM(BASE_COSTEO!$M$2:$M$680) -> 5104680 | G28: =(C28-C10)/C10 -> 0.045978529 | I28: {=_xlfn.LET( _xlpm.procedimientos,_xlfn.UNIQUE(_xlfn._xlws.FILTER(BASE_COSTEO!$C$2:$C$680,BASE_COSTEO!$C$2:$C$680<>"")), _xlpm.utilidades,_xlfn.MAP(_xlpm.procedimientos,_xlfn.LAMBDA(_xlpm.p, SUMIFS(BASE_COSTEO!$R$2:$R$680,BASE_COSTEO!$C$2:$C$680,_xlpm.p)+ SUMIFS(BASE_COSTEO!$V$2:$V$680,BASE_COSTEO!$C$2:$C$680,_xlpm.p)+ SUMIFS(BASE_COSTEO!$Z$2:$Z$680,BASE_COSTEO!$C$2:$C$680,_xlpm.p)- SUMIFS(BASE_COSTEO!$M$2:$M$680,BASE_COSTEO!$C$2:$C$680,_xlpm.p) )), INDEX(_xlpm.procedimientos,MATCH(MAX(_xlpm.utilidades),_xlpm.utilidades,0)) )} -> Alta Complejidad | K28: =((SUM(BASE_COSTEO!$R$2:$R$680)+SUM(BASE_COSTEO!$V$2:$V$680)+SUM(BASE_COSTEO!$Z$2:$Z$680)))/6 -> 19354634 | M28: {=IFERROR(ROUNDUP(SUM(BASE_COSTEO!$M$2:$M$680)/(((SUM(BASE_COSTEO!$R$2:$R$680)+SUM(BASE_COSTEO!$V$2:$V$680)+SUM(BASE_COSTEO!$Z$2:$Z$680))-SUM(BASE_COSTEO!$M$2:$M$680))/COUNTA(_xlfn.UNIQUE(_xlfn._xlws.FILTER(BASE_COSTEO!$D$2:$D$680,BASE_COSTEO!$D$2:$D$680<>"")))),0),0)&" Curaciones"} -> 87 Curaciones
D34: Etiquetas de fila | E34: % UTILIDAD ALTA COMPLEJIDAD_ | F34: % UTILIDAD MEDIANA COMPLEJIDAD_ | G34: % UTILIDAD BAJA COMPLEJIDAD_
D35: Mayo | E35: 5.5 | F35: 2.5 | G35: 2.5
D36: Junio | E36: 5.5 | F36: 2.5 | G36: 2.5
D37: Julio | E37: 5.5 | F37: 2.5 | G37: 2.5
D38: Agosto | E38: 5.5 | F38: 2.5 | G38: 2.5
D39: Septiembre | E39: 5.5 | F39: 2.5 | G39: 2.5
D40: Octubre | E40: 5.5 | F40: 2.5 | G40: 2.5
D41: Noviembre | E41: 5.5 | F41: 2.5 | G41: 2.5
D42: Total general | E42: 38.5 | F42: 17.5 | G42: 17.5
E48: CATEGORIA_COSTO | F48: INSUMO ALTA TECNOLOGIA
E49: PROCEDIMIENTO | F49: Curación de BAJA COMPLEJIDAD
E50: Mes | F50: Mayo
E52: Nombre | F52: _ | G52: Costo
E53: Mepilex Transfer Ag 15 x 20 cm | G53: 224100
E54: Mepilex Border Ag 10 x 30 cm | G54: 204000
E55: Mepilex Border Ag 10 x 25 cm | G55: 174700
E56: Mepilex Border Ag 10 x 20 cm | G56: 141600
E57: Mepilex Ag 15 x 15 cm | G57: 114900
E58: Mepilex Border Ag 10 x 10 cm | G58: 49200
E59: Mepilex Transfer 15 x 20 cm | G59: 49000
E60: Mextra Superabsorbent 17.5x22.5 cm | G60: 39800
E61: Mextra Superabsorbent 12.5x22.5 cm | G61: 38000
E62: Exufiber Ag+ 10 x 12 cm | G62: 36700
E63: Mepilex 15 x 15 cm | G63: 36700
E64: Exufiber 10 x 12 cm | G64: 28800
... E68: Total general | G68: 1215400

Sheet BASE_COSTEO
A1: Año | B1: Mes | C1: COMPLEJIDAD | D1: PROCEDIMIENTO | E1: CODIGO_CUPS | F1: TIEMPO_MINUTOS | G1: TIPO_REGISTRO | H1: CATEGORIA_COSTO | I1: ITEM | J1: CANTIDAD CURACIONES | K1: UNIDAD_MEDIDA | L1: COSTO_UNITARIO | M1: COSTO_TOTAL | N1: OBSERVACIONES | O1: PRECIO VENTA | P1: COSTO ALTA COMPLEJIDAD | Q1: % INCRE_ALTA | R1: PRECIO VTA ALTA COMPLEJIDAD | S1: % UTILIDAD ALTA COMPLEJIDAD | T1: COSTO MEDIANA COMPLEJIDAD | U1: % INCRE MEDIA | V1: PRECIO VTA MEDIANA COMPLEJIDAD | W1: % UTILIDAD MEDIANA COMPLEJIDAD | X1: COSTO BAJA COMPLEJIDAD | Y1: % INCRE BAJA | Z1: PRECIO VTA BAJA COMPLEJIDAD | AA1: % UTILIDAD BAJA COMPLEJIDAD | AB1: % CRECIMIENTO
A2: 2026 | B2: Mayo | C2: Gasto Administrativo | D2: Gasto Administrativo | G2: GASTO_ADMINISTRATIVO | H2: GASTO_ADMINISTRATIVO | I2: Gasto administrativo | J2: 10 | K2: MINUTOS | L2: 3000 | M2: 30000 | O2: =R2 -> 30000 | P2: =IF(C2="Alta Complejidad",M2,0) -> 0 | Q2: 0 | R2: =M2+(M2*Q2) -> 30000 | S2: =IFERROR(((R2-P2)/R2),0) -> 1 | T2: =IF(C2="Mediana Complejidad",M2,0) -> 0 | U2: 0 | V2: =(T2)+(T2*U2) -> 0 | W2: =IFERROR(((V2-T2)/V2),0) -> 0 | X2: =IF(C2="Baja Complejidad",M2,0) -> 0 | Y2: 0 | Z2: =(X2)+(X2*Y2) -> 0 | AA2: =IFERROR(((Z2-X2)/Z2),0) -> 0 | AB2: 0.1
A3: 2026 | B3: Mayo | C3: Gasto Administrativo | D3: Gasto Administrativo | G3: GASTO_ADMINISTRATIVO | H3: GASTO_ADMINISTRATIVO | I3: Arriendo | J3: 1 | K3: UND | L3: 2000000 | M3: 2000000 | O3: =R3 -> 2000000 | P3: =IF(C3="Alta Complejidad",M3,0) -> 0 | Q3: 0 | R3: =M3+(M3*Q3) -> 2000000 | S3: =IFERROR(((R3-P3)/R3),0) -> 1 | T3: =IF(C3="Mediana Complejidad",M3,0) -> 0 | U3: 0 | V3: =(T3)+(T3*U3) -> 0 | W3: =IFERROR(((V3-T3)/V3),0) -> 0 | X3: =IF(C3="Baja Complejidad",M3,0) -> 0 | Y3: 0 | Z3: =(X3)+(X3*Y3) -> 0 | AA3: =IFERROR(((Z3-X3)/Z3),0) -> 0 | AB3: 0.1
A4: 2026 | B4: Mayo | C4: Gasto Administrativo | D4: Gasto Administrativo | G4: GASTO_ADMINISTRATIVO | H4: GASTO_ADMINISTRATIVO | I4: Pauta Redes (google, facebook, tik tok, instagram) | J4: 1 | K4: UND | L4: 200000 | M4: 200000 | O4: =R4 -> 200000 | P4: =IF(C4="Alta Complejidad",M4,0) -> 0 | Q4: 0 | R4: =M4+(M4*Q4) -> 200000 | S4: =IFERROR(((R4-P4)/R4),0) -> 1 | T4: =IF(C4="Mediana Complejidad",M4,0) -> 0 | U4: 0 | V4: =(T4)+(T4*U4) -> 0 | W4: =IFERROR(((V4-T4)/V4),0) -> 0 | X4: =IF(C4="Baja Complejidad",M4,0) -> 0 | Y4: 0 | Z4: =(X4)+(X4*Y4) -> 0 | AA4: =IFERROR(((Z4-X4)/Z4),0) -> 0 | AB4: 0.1
A5: 2026 | B5: Junio | C5: Gasto Administrativo | D5: Gasto Administrativo | G5: GASTO_ADMINISTRATIVO | H5: GASTO_ADMINISTRATIVO | I5: Gasto administrativo | J5: 10 | K5: MINUTOS | L5: 3000 | M5: 30000 | O5: =R5 -> 30000 | P5: =IF(C5="Alta Complejidad",M5,0) -> 0 | Q5: 0 | R5: =M5+(M5*Q5) -> 30000 | S5: =IFERROR(((R5-P5)/R5),0) -> 1 | T5: =IF(C5="Mediana Complejidad",M5,0) -> 0 | U5: 0 | V5: =(T5)+(T5*U5) -> 0 | W5: =IFERROR(((V5-T5)/V5),0) -> 0 | X5: =IF(C5="Baja Complejidad",M5,0) -> 0 | Y5: 0 | Z5: =(X5)+(X5*Y5) -> 0 | AA5: =IFERROR(((Z5-X5)/Z5),0) -> 0 | AB5: 0.1
A6: 2026 | B6: Junio | C6: Gasto Administrativo | D6: Gasto Administrativo | G6: GASTO_ADMINISTRATIVO | H6: GASTO_ADMINISTRATIVO | I6: Arriendo | J6: 1 | K6: UND | L6: 2000000 | M6: 2000000 | O6: =R6 -> 2000000 | P6: =IF(C6="Alta Complejidad",M6,0) -> 0 | Q6: 0 | R6: =M6+(M6*Q6) -> 2000000 | S6: =IFERROR(((R6-P6)/R6),0) -> 1 | T6: =IF(C6="Mediana Complejidad",M6,0) -> 0 | U6: 0 | V6: =(T6)+(T6*U6) -> 0 | W6: =IFERROR(((V6-T6)/V6),0) -> 0 | X6: =IF(C6="Baja Complejidad",M6,0) -> 0 | Y6: 0 | Z6: =(X6)+(X6*Y6) -> 0 | AA6: =IFERROR(((Z6-X6)/Z6),0) -> 0 | AB6: 0.1
A7: 2026 | B7: Junio | C7: Gasto Administrativo | D7: Gasto Administrativo | G7: GASTO_ADMINISTRATIVO | H7: GASTO_ADMINISTRATIVO | I7: Pauta Redes (google, facebook, tik tok, instagram) | J7: 1 | K7: UND | L7: 200000 | M7: 200000 | O7: =R7 -> 200000 | P7: =IF(C7="Alta Complejidad",M7,0) -> 0 | Q7: 0 | R7: =M7+(M7*Q7) -> 200000 | S7: =IFERROR(((R7-P7)/R7),0) -> 1 | T7: =IF(C7="Mediana Complejidad",M7,0) -> 0 | U7: 0 | V7: =(T7)+(T7*U7) -> 0 | W7: =IFERROR(((V7-T7)/V7),0) -> 0 | X7: =IF(C7="Baja Complejidad",M7,0) -> 0 | Y7: 0 | Z7: =(X7)+(X7*Y7) -> 0 | AA7: =IFERROR(((Z7-X7)/Z7),0) -> 0 | AB7: 0.1
A8: 2026 | B8: Julio | C8: Gasto Administrativo | D8: Gasto Administrativo | G8: GASTO_ADMINISTRATIVO | H8: GASTO_ADMINISTRATIVO | I8: Gasto administrativo | J8: 10 | K8: MINUTOS | L8: 3000 | M8: 30000 | O8: =R8 -> 30000 | P8: =IF(C8="Alta Complejidad",M8,0) -> 0 | Q8: 0 | R8: =M8+(M8*Q8) -> 30000 | S8: =IFERROR(((R8-P8)/R8),0) -> 1 | T8: =IF(C8="Mediana Complejidad",M8,0) -> 0 | U8: 0 | V8: =(T8)+(T8*U8) -> 0 | W8: =IFERROR(((V8-T8)/V8),0) -> 0 | X8: =IF(C8="Baja Complejidad",M8,0) -> 0 | Y8: 0 | Z8: =(X8)+(X8*Y8) -> 0 | AA8: =IFERROR(((Z8-X8)/Z8),0) -> 0 | AB8: 0.1
A9: 2026 | B9: Julio | C9: Gasto Administrativo | D9: Gasto Administrativo | G9: GASTO_ADMINISTRATIVO | H9: GASTO_ADMINISTRATIVO | I9: Arriendo | J9: 1 | K9: UND | L9: 2000000 | M9: 2000000 | O9: =R9 -> 2000000 | P9: =IF(C9="Alta Complejidad",M9,0) -> 0 | Q9: 0 | R9: =M9+(M9*Q9) -> 2000000 | S9: =IFERROR(((R9-P9)/R9),0) -> 1 | T9: =IF(C9="Mediana Complejidad",M9,0) -> 0 | U9: 0 | V9: =(T9)+(T9*U9) -> 0 | W9: =IFERROR(((V9-T9)/V9),0) -> 0 | X9: =IF(C9="Baja Complejidad",M9,0) -> 0 | Y9: 0 | Z9: =(X9)+(X9*Y9) -> 0 | AA9: =IFERROR(((Z9-X9)/Z9),0) -> 0 | AB9: 0.1
A10: 2026 | B10: Julio | C10: Gasto Administrativo | D10: Gasto Administrativo | G10: GASTO_ADMINISTRATIVO | H10: GASTO_ADMINISTRATIVO | I10: Pauta Redes (google, facebook, tik tok, instagram) | J10: 1 | K10: UND | L10: 200000 | M10: 200000 | O10: =R10 -> 200000 | P10: =IF(C10="Alta Complejidad",M10,0) -> 0 | Q10: 0 | R10: =M10+(M10*Q10) -> 200000 | S10: =IFERROR(((R10-P10)/R10),0) -> 1 | T10: =IF(C10="Mediana Complejidad",M10,0) -> 0 | U10: 0 | V10: =(T10)+(T10*U10) -> 0 | W10: =IFERROR(((V10-T10)/V10),0) -> 0 | X10: =IF(C10="Baja Complejidad",M10,0) -> 0 | Y10: 0 | Z10: =(X10)+(X10*Y10) -> 0 | AA10: =IFERROR(((Z10-X10)/Z10),0) -> 0 | AB10: 0.1
A11: 2026 | B11: Agosto | C11: Gasto Administrativo | D11: Gasto Administrativo | G11: GASTO_ADMINISTRATIVO | H11: GASTO_ADMINISTRATIVO | I11: Gasto administrativo | J11: 10 | K11: MINUTOS | L11: 3000 | M11: 30000 | O11: =R11 -> 30000 | P11: =IF(C11="Alta Complejidad",M11,0) -> 0 | Q11: 0 | R11: =M11+(M11*Q11) -> 30000 | S11: =IFERROR(((R11-P11)/R11),0) -> 1 | T11: =IF(C11="Mediana Complejidad",M11,0) -> 0 | U11: 0 | V11: =(T11)+(T11*U11) -> 0 | W11: =IFERROR(((V11-T11)/V11),0) -> 0 | X11: =IF(C11="Baja Complejidad",M11,0) -> 0 | Y11: 0 | Z11: =(X11)+(X11*Y11) -> 0 | AA11: =IFERROR(((Z11-X11)/Z11),0) -> 0 | AB11: 0.1
A12: 2026 | B12: Agosto | C12: Gasto Administrativo | D12: Gasto Administrativo | G12: GASTO_ADMINISTRATIVO | H12: GASTO_ADMINISTRATIVO | I12: Arriendo | J12: 1 | K12: UND | L12: 2000000 | M12: 2000000 | O12: =R12 -> 2000000 | P12: =IF(C12="Alta Complejidad",M12,0) -> 0 | Q12: 0 | R12: =M12+(M12*Q12) -> 2000000 | S12: =IFERROR(((R12-P12)/R12),0) -> 1 | T12: =IF(C12="Mediana Complejidad",M12,0) -> 0 | U12: 0 | V12: =(T12)+(T12*U12) -> 0 | W12: =IFERROR(((V12-T12)/V12),0) -> 0 | X12: =IF(C12="Baja Complejidad",M12,0) -> 0 | Y12: 0 | Z12: =(X12)+(X12*Y12) -> 0 | AA12: =IFERROR(((Z12-X12)/Z12),0) -> 0 | AB12: 0.1
A13: 2026 | B13: Agosto | C13: Gasto Administrativo | D13: Gasto Administrativo | G13: GASTO_ADMINISTRATIVO | H13: GASTO_ADMINISTRATIVO | I13: Pauta Redes (google, facebook, tik tok, instagram) | J13: 1 | K13: UND | L13: 200000 | M13: 200000 | O13: =R13 -> 200000 | P13: =IF(C13="Alta Complejidad",M13,0) -> 0 | Q13: 0 | R13: =M13+(M13*Q13) -> 200000 | S13: =IFERROR(((R13-P13)/R13),0) -> 1 | T13: =IF(C13="Mediana Complejidad",M13,0) -> 0 | U13: 0 | V13: =(T13)+(T13*U13) -> 0 | W13: =IFERROR(((V13-T13)/V13),0) -> 0 | X13: =IF(C13="Baja Complejidad",M13,0) -> 0 | Y13: 0 | Z13: =(X13)+(X13*Y13) -> 0 | AA13: =IFERROR(((Z13-X13)/Z13),0) -> 0 | AB13: 0.1
... A22: 2026 | B22: Noviembre | C22: Gasto Administrativo | D22: Gasto Administrativo | G22: GASTO_ADMINISTRATIVO | H22: GASTO_ADMINISTRATIVO | I22: Pauta Redes (google, facebook, tik tok, instagram) | J22: 1 | K22: UND | L22: 200000 | M22: 200000 | O22: =R22 -> 200000 | P22: =IF(C22="Alta Complejidad",M22,0) -> 0 | Q22: 0 | R22: =M22+(M22*Q22) -> 200000 | S22: =IFERROR(((R22-P22)/R22),0) -> 1 | T22: =IF(C22="Mediana Complejidad",M22,0) -> 0 | U22: 0 | V22: =(T22)+(T22*U22) -> 0 | W22: =IFERROR(((V22-T22)/V22),0) -> 0 | X22: =IF(C22="Baja Complejidad",M22,0) -> 0 | Y22: 0 | Z22: =(X22)+(X22*Y22) -> 0 | AA22: =IFERROR(((Z22-X22)/Z22),0) -> 0 | AB22: 0.1
A23: 2026 | B23: Mayo | C23: Alta Complejidad | D23: Curación de ALTA COMPLEJIDAD | E23: G20 | G23: INSUMO | H23: INSUMO | I23: Guante examen talla M | J23: 4 | K23: UND | L23: 266 | M23: 1064 | O23: =R23 -> 1064 | P23: =IF(C23="Alta Complejidad",M23,0) -> 1064 | Q23: 0 | R23: =M23+(M23*Q23) -> 1064 | S23: =IFERROR(((R23-P23)/R23),0) -> 0 | T23: =IF(C23="Mediana Complejidad",M23,0) -> 0 | U23: 0 | V23: =(T23)+(T23*U23) -> 0 | W23: =IFERROR(((V23-T23)/V23),0) -> 0 | X23: =IF(C23="Baja Complejidad",M23,0) -> 0 | Y23: 0 | Z23: =(X23)+(X23*Y23) -> 0 | AA23: =IFERROR(((Z23-X23)/Z23),0) -> 0 | AB23: 0.1
A24: 2026 | B24: Mayo | C24: Alta Complejidad | D24: Curación de ALTA COMPLEJIDAD | E24: G68 | G24: INSUMO | H24: INSUMO | I24: Guante quirurgico esteril 7.0 | J24: 2 | K24: UND | L24: 1086.232 | M24: 2172.464 | O24: =R24 -> 2172.464 | P24: =IF(C24="Alta Complejidad",M24,0) -> 2172.464 | Q24: 0 | R24: =M24+(M24*Q24) -> 2172.464 | S24: =IFERROR(((R24-P24)/R24),0) -> 0 | T24: =IF(C24="Mediana Complejidad",M24,0) -> 0 | U24: 0 | V24: =(T24)+(T24*U24) -> 0 | W24: =IFERROR(((V24-T24)/V24),0) -> 0 | X24: =IF(C24="Baja Complejidad",M24,0) -> 0 | Y24: 0 | Z24: =(X24)+(X24*Y24) -> 0 | AA24: =IFERROR(((Z24-X24)/Z24),0) -> 0 | AB24: 0.1
A25: 2026 | B25: Mayo | C25: Alta Complejidad | D25: Curación de ALTA COMPLEJIDAD | E25: G75 | G25: INSUMO | H25: INSUMO | I25: Gasa esteril 7.5 X 7.5 sobre x 5 unid | J25: 10 | K25: UND | L25: 370 | M25: 3700 | O25: =R25 -> 3700 | P25: =IF(C25="Alta Complejidad",M25,0) -> 3700 | Q25: 0 | R25: =M25+(M25*Q25) -> 3700 | S25: =IFERROR(((R25-P25)/R25),0) -> 0 | T25: =IF(C25="Mediana Complejidad",M25,0) -> 0 | U25: 0 | V25: =(T25)+(T25*U25) -> 0 | W25: =IFERROR(((V25-T25)/V25),0) -> 0 | X25: =IF(C25="Baja Complejidad",M25,0) -> 0 | Y25: 0 | Z25: =(X25)+(X25*Y25) -> 0 | AA25: =IFERROR(((Z25-X25)/Z25),0) -> 0 | AB25: 0.1
A26: 2026 | B26: Mayo | C26: Alta Complejidad | D26: Curación de ALTA COMPLEJIDAD | E26: S60 | G26: INSUMO | H26: INSUMO | I26: Solucion Salina 0.9% Bolsa 500 ml | J26: 2 | K26: UND | L26: 2643 | M26: 5286 | O26: =R26 -> 5286 | P26: =IF(C26="Alta Complejidad",M26,0) -> 5286 | Q26: 0 | R26: =M26+(M26*Q26) -> 5286 | S26: =IFERROR(((R26-P26)/R26),0) -> 0 | T26: =IF(C26="Mediana Complejidad",M26,0) -> 0 | U26: 0 | V26: =(T26)+(T26*U26) -> 0 | W26: =IFERROR(((V26-T26)/V26),0) -> 0 | X26: =IF(C26="Baja Complejidad",M26,0) -> 0 | Y26: 0 | Z26: =(X26)+(X26*Y26) -> 0 | AA26: =IFERROR(((Z26-X26)/Z26),0) -> 0 | AB26: 0.1
A27: 2026 | B27: Mayo | C27: Alta Complejidad | D27: Curación de ALTA COMPLEJIDAD | E27: T502 | G27: INSUMO | H27: INSUMO | I27: Tapabocas Estandar 1405 | J27: 5 | K27: UND | L27: 135.66 | M27: 678.3 | O27: =R27 -> 678.3 | P27: =IF(C27="Alta Complejidad",M27,0) -> 678.3 | Q27: 0 | R27: =M27+(M27*Q27) -> 678.3 | S27: =IFERROR(((R27-P27)/R27),0) -> 0 | T27: =IF(C27="Mediana Complejidad",M27,0) -> 0 | U27: 0 | V27: =(T27)+(T27*U27) -> 0 | W27: =IFERROR(((V27-T27)/V27),0) -> 0 | X27: =IF(C27="Baja Complejidad",M27,0) -> 0 | Y27: 0 | Z27: =(X27)+(X27*Y27) -> 0 | AA27: =IFERROR(((Z27-X27)/Z27),0) -> 0 | AB27: 0.1
A28: 2026 | B28: Mayo | C28: Alta Complejidad | D28: Curación de ALTA COMPLEJIDAD | E28: B10 | G28: INSUMO | H28: INSUMO | I28: Bata Desechable con Manga No Esteril | J28: 2 | K28: UND | L28: 3808 | M28: 7616 | O28: =R28 -> 7616 | P28: =IF(C28="Alta Complejidad",M28,0) -> 7616 | Q28: 0 | R28: =M28+(M28*Q28) -> 7616 | S28: =IFERROR(((R28-P28)/R28),0) -> 0 | T28: =IF(C28="Mediana Complejidad",M28,0) -> 0 | U28: 0 | V28: =(T28)+(T28*U28) -> 0 | W28: =IFERROR(((V28-T28)/V28),0) -> 0 | X28: =IF(C28="Baja Complejidad",M28,0) -> 0 | Y28: 0 | Z28: =(X28)+(X28*Y28) -> 0 | AA28: =IFERROR(((Z28-X28)/Z28),0) -> 0 | AB28: 0.1
A29: 2026 | B29: Mayo | C29: Alta Complejidad | D29: Curación de ALTA COMPLEJIDAD | E29: G07 | G29: INSUMO | H29: INSUMO | I29: Gorro Desechable Estandar Blanco | J29: 2 | K29: UND | L29: 111.86 | M29: 223.72 | O29: =R29 -> 223.72 | P29: =IF(C29="Alta Complejidad",M29,0) -> 223.72 | Q29: 0 | R29: =M29+(M29*Q29) -> 223.72 | S29: =IFERROR(((R29-P29)/R29),0) -> 0 | T29: =IF(C29="Mediana Complejidad",M29,0) -> 0 | U29: 0 | V29: =(T29)+(T29*U29) -> 0 | W29: =IFERROR(((V29-T29)/V29),0) -> 0 | X29: =IF(C29="Baja Complejidad",M29,0) -> 0 | Y29: 0 | Z29: =(X29)+(X29*Y29) -> 0 | AA29: =IFERROR(((Z29-X29)/Z29),0) -> 0 | AB29: 0.1
A30: 2026 | B30: Mayo | C30: Alta Complejidad | D30: Curación de ALTA COMPLEJIDAD | E30: 360100 | G30: INSUMO | H30: INSUMO | I30: Granudacyn Solución 250 ml Spray | J30: 10 | K30: UND | L30: 80300 | M30: 3212 | O30: =R30 -> 3212 | P30: =IF(C30="Alta Complejidad",M30,0) -> 3212 | Q30: 0 | R30: =M30+(M30*Q30) -> 3212 | S30: =IFERROR(((R30-P30)/R30),0) -> 0 | T30: =IF(C30="Mediana Complejidad",M30,0) -> 0 | U30: 0 | V30: =(T30)+(T30*U30) -> 0 | W30: =IFERROR(((V30-T30)/V30),0) -> 0 | X30: =IF(C30="Baja Complejidad",M30,0) -> 0 | Y30: 0 | Z30: =(X30)+(X30*Y30) -> 0 | AA30: =IFERROR(((Z30-X30)/Z30),0) -> 0 | AB30: 0.1
A31: 2026 | B31: Mayo | C31: Alta Complejidad | D31: Curación de ALTA COMPLEJIDAD | E31: T180 | G31: INSUMO | H31: INSUMO | I31: Toalla de Manos Pre-cortada Natural R7 | J31: 5 | K31: UND | L31: 17888.08 | M31: 89440.4 | O31: =R31 -> 89440.4 | P31: =IF(C31="Alta Complejidad",M31,0) -> 89440.4 | Q31: 0 | R31: =M31+(M31*Q31) -> 89440.4 | S31: =IFERROR(((R31-P31)/R31),0) -> 0 | T31: =IF(C31="Mediana Complejidad",M31,0) -> 0 | U31: 0 | V31: =(T31)+(T31*U31) -> 0 | W31: =IFERROR(((V31-T31)/V31),0) -> 0 | X31: =IF(C31="Baja Complejidad",M31,0) -> 0 | Y31: 0 | Z31: =(X31)+(X31*Y31) -> 0 | AA31: =IFERROR(((Z31-X31)/Z31),0) -> 0 | AB31: 0.1
A32: 2026 | B32: Mayo | C32: Alta Complejidad | D32: Curación de ALTA COMPLEJIDAD | E32: H15 | G32: INSUMO | H32: INSUMO | I32: Hoja para bisturi 15 | J32: 2 | K32: UND | L32: 337.38379 | M32: 674.76758 | O32: =R32 -> 674.76758 | P32: =IF(C32="Alta Complejidad",M32,0) -> 674.76758 | Q32: 0 | R32: =M32+(M32*Q32) -> 674.76758 | S32: =IFERROR(((R32-P32)/R32),0) -> 0 | T32: =IF(C32="Mediana Complejidad",M32,0) -> 0 | U32: 0 | V32: =(T32)+(T32*U32) -> 0 | W32: =IFERROR(((V32-T32)/V32),0) -> 0 | X32: =IF(C32="Baja Complejidad",M32,0) -> 0 | Y32: 0 | Z32: =(X32)+(X32*Y32) -> 0 | AA32: =IFERROR(((Z32-X32)/Z32),0) -> 0 | AB32: 0.1
A33: 2026 | B33: Mayo | C33: Alta Complejidad | D33: Curación de ALTA COMPLEJIDAD | E33: 2438 | G33: INSUMO | H33: INSUMO | I33: Tubifast 10m Azul | J33: 2 | K33: UND | L33: 67900 | M33: 13580 | O33: =R33 -> 13580 | P33: =IF(C33="Alta Complejidad",M33,0) -> 13580 | Q33: 0 | R33: =M33+(M33*Q33) -> 13580 | S33: =IFERROR(((R33-P33)/R33),0) -> 0 | T33: =IF(C33="Mediana Complejidad",M33,0) -> 0 | U33: 0 | V33: =(T33)+(T33*U33) -> 0 | W33: =IFERROR(((V33-T33)/V33),0) -> 0 | X33: =IF(C33="Baja Complejidad",M33,0) -> 0 | Y33: 0 | Z33: =(X33)+(X33*Y33) -> 0 | AA33: =IFERROR(((Z33-X33)/Z33),0) -> 0 | AB33: 0.1
A34: 2026 | B34: Mayo | C34: Alta Complejidad | D34: Curación de ALTA COMPLEJIDAD | E34: 2434 | G34: INSUMO | H34: INSUMO | I34: Tubifast 10m Rojo | J34: 2 | K34: UND | L34: 50300 | M34: 10060 | O34: =R34 -> 10060 | P34: =IF(C34="Alta Complejidad",M34,0) -> 10060 | Q34: 0 | R34: =M34+(M34*Q34) -> 10060 | S34: =IFERROR(((R34-P34)/R34),0) -> 0 | T34: =IF(C34="Mediana Complejidad",M34,0) -> 0 | U34: 0 | V34: =(T34)+(T34*U34) -> 0 | W34: =IFERROR(((V34-T34)/V34),0) -> 0 | X34: =IF(C34="Baja Complejidad",M34,0) -> 0 | Y34: 0 | Z34: =(X34)+(X34*Y34) -> 0 | AA34: =IFERROR(((Z34-X34)/Z34),0) -> 0 | AB34: 0.1
A35: 2026 | B35: Mayo | C35: Alta Complejidad | D35: Curación de ALTA COMPLEJIDAD | E35: 3505 | G35: INSUMO | H35: INSUMO | I35: Setopress 10 cm x 3.5 m Relaxed x 12 | J35: 2 | K35: UND | L35: 43500 | M35: 7250 | O35: =R35 -> 7250 | P35: =IF(C35="Alta Complejidad",M35,0) -> 7250 | Q35: 0 | R35: =M35+(M35*Q35) -> 7250 | S35: =IFERROR(((R35-P35)/R35),0) -> 0 | T35: =IF(C35="Mediana Complejidad",M35,0) -> 0 | U35: 0 | V35: =(T35)+(T35*U35) -> 0 | W35: =IFERROR(((V35-T35)/V35),0) -> 0 | X35: =IF(C35="Baja Complejidad",M35,0) -> 0 | Y35: 0 | Z35: =(X35)+(X35*Y35) -> 0 | AA35: =IFERROR(((Z35-X35)/Z35),0) -> 0 | AB35: 0.1
A36: 2026 | B36: Mayo | C36: Alta Complejidad | D36: Curación de ALTA COMPLEJIDAD | F36: 1800 | G36: MANO_OBRA | H36: MANO_OBRA | I36: Enfermera | J36: 60 | K36: MINUTOS | L36: 20894.4 | M36: =+L36*J36 -> 1253664 | O36: =R36 -> 1253664 | P36: =IF(C36="Alta Complejidad",M36,0) -> 1253664 | Q36: 0 | R36: =M36+(M36*Q36) -> 1253664 | S36: =IFERROR(((R36-P36)/R36),0) -> 0 | T36: =IF(C36="Mediana Complejidad",M36,0) -> 0 | U36: 0 | V36: =(T36)+(T36*U36) -> 0 | W36: =IFERROR(((V36-T36)/V36),0) -> 0 | X36: =IF(C36="Baja Complejidad",M36,0) -> 0 | Y36: 0 | Z36: =(X36)+(X36*Y36) -> 0 | AA36: =IFERROR(((Z36-X36)/Z36),0) -> 0 | AB36: 0.1
A37: 2026 | B37: Mayo | C37: Alta Complejidad | D37: Curación de ALTA COMPLEJIDAD | F37: 900 | G37: MANO_OBRA | H37: MANO_OBRA | I37: Auxiliar enfermeria | J37: 60 | K37: MINUTOS | L37: 6048.3 | M37: =+L37*J37 -> 362898 | O37: =R37 -> 362898 | P37: =IF(C37="Alta Complejidad",M37,0) -> 362898 | Q37: 0 | R37: =M37+(M37*Q37) -> 362898 | S37: =IFERROR(((R37-P37)/R37),0) -> 0 | T37: =IF(C37="Mediana Complejidad",M37,0) -> 0 | U37: 0 | V37: =(T37)+(T37*U37) -> 0 | W37: =IFERROR(((V37-T37)/V37),0) -> 0 | X37: =IF(C37="Baja Complejidad",M37,0) -> 0 | Y37: 0 | Z37: =(X37)+(X37*Y37) -> 0 | AA37: =IFERROR(((Z37-X37)/Z37),0) -> 0 | AB37: 0.1
A38: 2026 | B38: Mayo | C38: Alta Complejidad | D38: Curación de ALTA COMPLEJIDAD | F38: 600 | G38: MANO_OBRA | H38: MANO_OBRA | I38: Cirujano vascular | J38: 60 | K38: MINUTOS | L38: 35000 | M38: =+L38*J38 -> 2100000 | O38: =R38 -> 2100000 | P38: =IF(C38="Alta Complejidad",M38,0) -> 2100000 | Q38: 0 | R38: =M38+(M38*Q38) -> 2100000 | S38: =IFERROR(((R38-P38)/R38),0) -> 0 | T38: =IF(C38="Mediana Complejidad",M38,0) -> 0 | U38: 0 | V38: =(T38)+(T38*U38) -> 0 | W38: =IFERROR(((V38-T38)/V38),0) -> 0 | X38: =IF(C38="Baja Complejidad",M38,0) -> 0 | Y38: 0 | Z38: =(X38)+(X38*Y38) -> 0 | AA38: =IFERROR(((Z38-X38)/Z38),0) -> 0 | AB38: 0.1
A39: 2026 | B39: Mayo | C39: Alta Complejidad | D39: Curación de ALTA COMPLEJIDAD | F39: 600 | G39: MANO_OBRA | H39: MANO_OBRA | I39: Nutricionista | J39: 60 | K39: MINUTOS | L39: 25000 | M39: =+L39*J39 -> 1500000 | O39: =R39 -> 1500000 | P39: =IF(C39="Alta Complejidad",M39,0) -> 1500000 | Q39: 0 | R39: =M39+(M39*Q39) -> 1500000 | S39: =IFERROR(((R39-P39)/R39),0) -> 0 | T39: =IF(C39="Mediana Complejidad",M39,0) -> 0 | U39: 0 | V39: =(T39)+(T39*U39) -> 0 | W39: =IFERROR(((V39-T39)/V39),0) -> 0 | X39: =IF(C39="Baja Complejidad",M39,0) -> 0 | Y39: 0 | Z39: =(X39)+(X39*Y39) -> 0 | AA39: =IFERROR(((Z39-X39)/Z39),0) -> 0 | AB39: 0.1
A40: 2026 | B40: Mayo | C40: Alta Complejidad | D40: Curación de ALTA COMPLEJIDAD | F40: 600 | G40: MANO_OBRA | H40: MANO_OBRA | I40: Terapeuta fisico | J40: 60 | K40: MINUTOS | L40: 20000 | M40: =+L40*J40 -> 1200000 | O40: =R40 -> 1200000 | P40: =IF(C40="Alta Complejidad",M40,0) -> 1200000 | Q40: 0 | R40: =M40+(M40*Q40) -> 1200000 | S40: =IFERROR(((R40-P40)/R40),0) -> 0 | T40: =IF(C40="Mediana Complejidad",M40,0) -> 0 | U40: 0 | V40: =(T40)+(T40*U40) -> 0 | W40: =IFERROR(((V40-T40)/V40),0) -> 0 | X40: =IF(C40="Baja Complejidad",M40,0) -> 0 | Y40: 0 | Z40: =(X40)+(X40*Y40) -> 0 | AA40: =IFERROR(((Z40-X40)/Z40),0) -> 0 | AB40: 0.1
A41: 2026 | B41: Junio | C41: Alta Complejidad | D41: Curación de ALTA COMPLEJIDAD | E41: G20 | G41: INSUMO | H41: INSUMO | I41: Guante examen talla M | J41: 4 | K41: UND | L41: 266 | M41: 1064 | O41: =R41 -> 1064 | P41: =IF(C41="Alta Complejidad",M41,0) -> 1064 | Q41: 0 | R41: =M41+(M41*Q41) -> 1064 | S41: =IFERROR(((R41-P41)/R41),0) -> 0 | T41: =IF(C41="Mediana Complejidad",M41,0) -> 0 | U41: 0 | V41: =(T41)+(T41*U41) -> 0 | W41: =IFERROR(((V41-T41)/V41),0) -> 0 | X41: =IF(C41="Baja Complejidad",M41,0) -> 0 | Y41: 0 | Z41: =(X41)+(X41*Y41) -> 0 | AA41: =IFERROR(((Z41-X41)/Z41),0) -> 0 | AB41: 0.1
A42: 2026 | B42: Junio | C42: Alta Complejidad | D42: Curación de ALTA COMPLEJIDAD | E42: G68 | G42: INSUMO | H42: INSUMO | I42: Guante quirurgico esteril 7.0 | J42: 2 | K42: UND | L42: 1086.232 | M42: 2172.464 | O42: =R42 -> 2172.464 | P42: =IF(C42="Alta Complejidad",M42,0) -> 2172.464 | Q42: 0 | R42: =M42+(M42*Q42) -> 2172.464 | S42: =IFERROR(((R42-P42)/R42),0) -> 0 | T42: =IF(C42="Mediana Complejidad",M42,0) -> 0 | U42: 0 | V42: =(T42)+(T42*U42) -> 0 | W42: =IFERROR(((V42-T42)/V42),0) -> 0 | X42: =IF(C42="Baja Complejidad",M42,0) -> 0 | Y42: 0 | Z42: =(X42)+(X42*Y42) -> 0 | AA42: =IFERROR(((Z42-X42)/Z42),0) -> 0 | AB42: 0.1
A43: 2026 | B43: Junio | C43: Alta Complejidad | D43: Curación de ALTA COMPLEJIDAD | E43: G75 | G43: INSUMO | H43: INSUMO | I43: Gasa esteril 7.5 X 7.5 sobre x 5 unid | J43: 10 | K43: UND | L43: 370 | M43: 3700 | O43: =R43 -> 3700 | P43: =IF(C43="Alta Complejidad",M43,0) -> 3700 | Q43: 0 | R43: =M43+(M43*Q43) -> 3700 | S43: =IFERROR(((R43-P43)/R43),0) -> 0 | T43: =IF(C43="Mediana Complejidad",M43,0) -> 0 | U43: 0 | V43: =(T43)+(T43*U43) -> 0 | W43: =IFERROR(((V43-T43)/V43),0) -> 0 | X43: =IF(C43="Baja Complejidad",M43,0) -> 0 | Y43: 0 | Z43: =(X43)+(X43*Y43) -> 0 | AA43: =IFERROR(((Z43-X43)/Z43),0) -> 0 | AB43: 0.1
A44: 2026 | B44: Junio | C44: Alta Complejidad | D44: Curación de ALTA COMPLEJIDAD | E44: S60 | G44: INSUMO | H44: INSUMO | I44: Solucion Salina 0.9% Bolsa 500 ml | J44: 2 | K44: UND | L44: 2643 | M44: 5286 | O44: =R44 -> 5286 | P44: =IF(C44="Alta Complejidad",M44,0) -> 5286 | Q44: 0 | R44: =M44+(M44*Q44) -> 5286 | S44: =IFERROR(((R44-P44)/R44),0) -> 0 | T44: =IF(C44="Mediana Complejidad",M44,0) -> 0 | U44: 0 | V44: =(T44)+(T44*U44) -> 0 | W44: =IFERROR(((V44-T44)/V44),0) -> 0 | X44: =IF(C44="Baja Complejidad",M44,0) -> 0 | Y44: 0 | Z44: =(X44)+(X44*Y44) -> 0 | AA44: =IFERROR(((Z44-X44)/Z44),0) -> 0 | AB44: 0.1
A45: 2026 | B45: Junio | C45: Alta Complejidad | D45: Curación de ALTA COMPLEJIDAD | E45: T502 | G45: INSUMO | H45: INSUMO | I45: Tapabocas Estandar 1405 | J45: 5 | K45: UND | L45: 135.66 | M45: 678.3 | O45: =R45 -> 678.3 | P45: =IF(C45="Alta Complejidad",M45,0) -> 678.3 | Q45: 0 | R45: =M45+(M45*Q45) -> 678.3 | S45: =IFERROR(((R45-P45)/R45),0) -> 0 | T45: =IF(C45="Mediana Complejidad",M45,0) -> 0 | U45: 0 | V45: =(T45)+(T45*U45) -> 0 | W45: =IFERROR(((V45-T45)/V45),0) -> 0 | X45: =IF(C45="Baja Complejidad",M45,0) -> 0 | Y45: 0 | Z45: =(X45)+(X45*Y45) -> 0 | AA45: =IFERROR(((Z45-X45)/Z45),0) -> 0 | AB45: 0.1
A46: 2026 | B46: Junio | C46: Alta Complejidad | D46: Curación de ALTA COMPLEJIDAD | E46: B10 | G46: INSUMO | H46: INSUMO | I46: Bata Desechable con Manga No Esteril | J46: 2 | K46: UND | L46: 3808 | M46: 7616 | O46: =R46 -> 7616 | P46: =IF(C46="Alta Complejidad",M46,0) -> 7616 | Q46: 0 | R46: =M46+(M46*Q46) -> 7616 | S46: =IFERROR(((R46-P46)/R46),0) -> 0 | T46: =IF(C46="Mediana Complejidad",M46,0) -> 0 | U46: 0 | V46: =(T46)+(T46*U46) -> 0 | W46: =IFERROR(((V46-T46)/V46),0) -> 0 | X46: =IF(C46="Baja Complejidad",M46,0) -> 0 | Y46: 0 | Z46: =(X46)+(X46*Y46) -> 0 | AA46: =IFERROR(((Z46-X46)/Z46),0) -> 0 | AB46: 0.1
A47: 2026 | B47: Junio | C47: Alta Complejidad | D47: Curación de ALTA COMPLEJIDAD | E47: G07 | G47: INSUMO | H47: INSUMO | I47: Gorro Desechable Estandar Blanco | J47: 2 | K47: UND | L47: 111.86 | M47: 223.72 | O47: =R47 -> 223.72 | P47: =IF(C47="Alta Complejidad",M47,0) -> 223.72 | Q47: 0 | R47: =M47+(M47*Q47) -> 223.72 | S47: =IFERROR(((R47-P47)/R47),0) -> 0 | T47: =IF(C47="Mediana Complejidad",M47,0) -> 0 | U47: 0 | V47: =(T47)+(T47*U47) -> 0 | W47: =IFERROR(((V47-T47)/V47),0) -> 0 | X47: =IF(C47="Baja Complejidad",M47,0) -> 0 | Y47: 0 | Z47: =(X47)+(X47*Y47) -> 0 | AA47: =IFERROR(((Z47-X47)/Z47),0) -> 0 | AB47: 0.1
A48: 2026 | B48: Junio | C48: Alta Complejidad | D48: Curación de ALTA COMPLEJIDAD | E48: 360100 | G48: INSUMO | H48: INSUMO | I48: Granudacyn Solución 250 ml Spray | J48: 10 | K48: UND | L48: 80300 | M48: 3212 | O48: =R48 -> 3212 | P48: =IF(C48="Alta Complejidad",M48,0) -> 3212 | Q48: 0 | R48: =M48+(M48*Q48) -> 3212 | S48: =IFERROR(((R48-P48)/R48),0) -> 0 | T48: =IF(C48="Mediana Complejidad",M48,0) -> 0 | U48: 0 | V48: =(T48)+(T48*U48) -> 0 | W48: =IFERROR(((V48-T48)/V48),0) -> 0 | X48: =IF(C48="Baja Complejidad",M48,0) -> 0 | Y48: 0 | Z48: =(X48)+(X48*Y48) -> 0 | AA48: =IFERROR(((Z48-X48)/Z48),0) -> 0 | AB48: 0.1
...

Sheet formulas
A1: FORMULAS APLICADASD
A2: PUNTO EQUILIBRIO
A8: MARGEN
